2025-04-26 23:47:36,218: Error running WSGI application
2025-04-26 23:47:36,227: AttributeError: module 'sqlalchemy' has no attribute '__all__'. Did you mean: '__file__'?
2025-04-26 23:47:36,227:   File "/var/www/creditapp_pythonanywhere_com_wsgi.py", line 10, in <module>
2025-04-26 23:47:36,227:     from app import create_app
2025-04-26 23:47:36,227: 
2025-04-26 23:47:36,227:   File "/home/creditapp/app/app.py", line 7, in <module>
2025-04-26 23:47:36,228:     db = SQLAlchemy()
2025-04-26 23:47:36,228: 
2025-04-26 23:47:36,228:   File "/home/creditapp/.local/lib/python3.13/site-packages/flask_sqlalchemy/__init__.py", line 758, in __init__
2025-04-26 23:47:36,228:     _include_sqlalchemy(self, query_class)
2025-04-26 23:47:36,228:     ~~~~~~~~~~~~~~~~~~~^^^^^^^^^^^^^^^^^^^
2025-04-26 23:47:36,228: 
2025-04-26 23:47:36,228:   File "/home/creditapp/.local/lib/python3.13/site-packages/flask_sqlalchemy/__init__.py", line 112, in _include_sqlalchemy
2025-04-26 23:47:36,228:     for key in module.__all__:
2025-04-26 23:47:36,228:                ^^^^^^^^^^^^^^
2025-04-26 23:47:36,228: 
2025-04-26 23:47:36,228:   File "/usr/local/lib/python3.13/site-packages/sqlalchemy/__init__.py", line 294, in __getattr__
2025-04-26 23:47:36,228:     raise AttributeError(f"module {__name__!r} has no attribute {name!r}")
2025-04-26 23:47:36,229: ***************************************************
2025-04-26 23:47:36,229: If you're seeing an import error and don't know why,
2025-04-26 23:47:36,229: we have a dedicated help page to help you debug: 
2025-04-26 23:47:36,229: https://help.pythonanywhere.com/pages/DebuggingImportError/
2025-04-26 23:47:36,229: ***************************************************
2025-04-26 23:53:56,765: Exception on /login [GET]
Traceback (most recent call last):
  File "/home/creditapp/.local/lib/python3.13/site-packages/flask/app.py", line 2528, in wsgi_app
    response = self.full_dispatch_request()
  File "/home/creditapp/.local/lib/python3.13/site-packages/flask/app.py", line 1825, in full_dispatch_request
    rv = self.handle_user_exception(e)
  File "/home/creditapp/.local/lib/python3.13/site-packages/flask/app.py", line 1823, in full_dispatch_request
    rv = self.dispatch_request()
  File "/home/creditapp/.local/lib/python3.13/site-packages/flask/app.py", line 1799, in dispatch_request
    return self.ensure_sync(self.view_functions[rule.endpoint])(**view_args)
           ~~~~~~~~~~~~~~~~~~~~~~~~~~~~~~~~~~~~~~~~~~~~~~~~~~~~^^^^^^^^^^^^^
  File "/home/creditapp/app/app_simple.py", line 250, in login
    return render_template('auth/login.html', now=datetime.now())
  File "/home/creditapp/.local/lib/python3.13/site-packages/flask/templating.py", line 147, in render_template
    return _render(app, template, context)
  File "/home/creditapp/.local/lib/python3.13/site-packages/flask/templating.py", line 130, in _render
    rv = template.render(context)
  File "/usr/local/lib/python3.13/site-packages/jinja2/environment.py", line 1304, in render
    self.environment.handle_exception()
    ~~~~~~~~~~~~~~~~~~~~~~~~~~~~~~~~~^^
  File "/usr/local/lib/python3.13/site-packages/jinja2/environment.py", line 939, in handle_exception
    raise rewrite_traceback_stack(source=source)
  File "/home/creditapp/app/templates/auth/login.html", line 66, in top-level template code
    <form class="login-form" method="POST" action="{{ url_for('auth.login') }}">
    ^^^^^^^^^^^^^
  File "/home/creditapp/.local/lib/python3.13/site-packages/flask/app.py", line 2034, in url_for
    return self.handle_url_build_error(error, endpoint, values)
           ~~~~~~~~~~~~~~~~~~~~~~~~~~~^^^^^^^^^^^^^^^^^^^^^^^^^
  File "/home/creditapp/.local/lib/python3.13/site-packages/flask/app.py", line 2023, in url_for
    rv = url_adapter.build(  # type: ignore[union-attr]
        endpoint,
    ...<3 lines>...
        force_external=_external,
    )
  File "/home/creditapp/.local/lib/python3.13/site-packages/werkzeug/routing/map.py", line 917, in build
    raise BuildError(endpoint, values, method, self)
werkzeug.routing.exceptions.BuildError: Could not build url for endpoint 'auth.login'. Did you mean 'login' instead?
2025-04-26 23:56:41,544: Exception on /login [GET]
Traceback (most recent call last):
  File "/home/creditapp/.local/lib/python3.13/site-packages/flask/app.py", line 2528, in wsgi_app
    response = self.full_dispatch_request()
  File "/home/creditapp/.local/lib/python3.13/site-packages/flask/app.py", line 1825, in full_dispatch_request
    rv = self.handle_user_exception(e)
  File "/home/creditapp/.local/lib/python3.13/site-packages/flask/app.py", line 1823, in full_dispatch_request
    rv = self.dispatch_request()
  File "/home/creditapp/.local/lib/python3.13/site-packages/flask/app.py", line 1799, in dispatch_request
    return self.ensure_sync(self.view_functions[rule.endpoint])(**view_args)
           ~~~~~~~~~~~~~~~~~~~~~~~~~~~~~~~~~~~~~~~~~~~~~~~~~~~~^^^^^^^^^^^^^
  File "/home/creditapp/.local/lib/python3.13/site-packages/flask/templating.py", line 130, in _render
    rv = template.render(context)
  File "/usr/local/lib/python3.13/site-packages/jinja2/environment.py", line 1304, in render
    self.environment.handle_exception()
    ~~~~~~~~~~~~~~~~~~~~~~~~~~~~~~~~~^^
  File "/usr/local/lib/python3.13/site-packages/jinja2/environment.py", line 939, in handle_exception
    raise rewrite_traceback_stack(source=source)
  File "/home/creditapp/app/templates/auth/login.html", line 66, in top-level template code
    <form class="login-form" method="POST" action="{{ url_for('auth.login') }}">
    ^^^^^^^^^^^^^
  File "/home/creditapp/.local/lib/python3.13/site-packages/flask/app.py", line 2034, in url_for
    return self.handle_url_build_error(error, endpoint, values)
           ~~~~~~~~~~~~~~~~~~~~~~~~~~~^^^^^^^^^^^^^^^^^^^^^^^^^
  File "/home/creditapp/.local/lib/python3.13/site-packages/flask/app.py", line 2023, in url_for
    rv = url_adapter.build(  # type: ignore[union-attr]
        endpoint,
    ...<3 lines>...
        force_external=_external,
    )
  File "/home/creditapp/.local/lib/python3.13/site-packages/werkzeug/routing/map.py", line 917, in build
    raise BuildError(endpoint, values, method, self)
werkzeug.routing.exceptions.BuildError: Could not build url for endpoint 'auth.login'. Did you mean 'login' instead?
2025-04-27 00:29:58,929: Exception on / [GET]
Traceback (most recent call last):
  File "/home/creditapp/.local/lib/python3.13/site-packages/flask/app.py", line 2528, in wsgi_app
    response = self.full_dispatch_request()
  File "/home/creditapp/.local/lib/python3.13/site-packages/flask/app.py", line 1825, in full_dispatch_request
    rv = self.handle_user_exception(e)
  File "/home/creditapp/.local/lib/python3.13/site-packages/flask/app.py", line 1823, in full_dispatch_request
    rv = self.dispatch_request()
  File "/home/creditapp/.local/lib/python3.13/site-packages/flask/app.py", line 1799, in dispatch_request
    return self.ensure_sync(self.view_functions[rule.endpoint])(**view_args)
           ~~~~~~~~~~~~~~~~~~~~~~~~~~~~~~~~~~~~~~~~~~~~~~~~~~~~^^^^^^^^^^^^^
  File "/home/creditapp/.local/lib/python3.13/site-packages/flask_login/utils.py", line 290, in decorated_view
    return current_app.ensure_sync(func)(*args, **kwargs)
           ~~~~~~~~~~~~~~~~~~~~~~~~~~~~~^^^^^^^^^^^^^^^^^
  File "/home/creditapp/app/app_simple.py", line 424, in dashboard
    return render_template('admin/dashboard.html',
                          total_clientes=total_clientes,
    ...<2 lines>...
                          creditos_recientes=creditos_recientes,
                          abonos_recientes=abonos_recientes)
  File "/home/creditapp/.local/lib/python3.13/site-packages/flask/templating.py", line 146, in render_template
    template = app.jinja_env.get_or_select_template(template_name_or_list)
  File "/usr/local/lib/python3.13/site-packages/jinja2/environment.py", line 1084, in get_or_select_template
    return self.get_template(template_name_or_list, parent, globals)
           ~~~~~~~~~~~~~~~~~^^^^^^^^^^^^^^^^^^^^^^^^^^^^^^^^^^^^^^^^
  File "/usr/local/lib/python3.13/site-packages/jinja2/environment.py", line 1013, in get_template
    return self._load_template(name, globals)
           ~~~~~~~~~~~~~~~~~~~^^^^^^^^^^^^^^^
  File "/usr/local/lib/python3.13/site-packages/jinja2/environment.py", line 972, in _load_template
    template = self.loader.load(self, name, self.make_globals(globals))
  File "/usr/local/lib/python3.13/site-packages/jinja2/loaders.py", line 126, in load
    source, filename, uptodate = self.get_source(environment, name)
                                 ~~~~~~~~~~~~~~~^^^^^^^^^^^^^^^^^^^
  File "/home/creditapp/.local/lib/python3.13/site-packages/flask/templating.py", line 62, in get_source
    return self._get_source_fast(environment, template)
           ~~~~~~~~~~~~~~~~~~~~~^^^^^^^^^^^^^^^^^^^^^^^
  File "/home/creditapp/.local/lib/python3.13/site-packages/flask/templating.py", line 98, in _get_source_fast
    raise TemplateNotFound(template)
jinja2.exceptions.TemplateNotFound: admin/dashboard.html
2025-04-27 00:30:20,525: Exception on / [GET]
Traceback (most recent call last):
  File "/home/creditapp/.local/lib/python3.13/site-packages/flask/app.py", line 2528, in wsgi_app
    response = self.full_dispatch_request()
  File "/home/creditapp/.local/lib/python3.13/site-packages/flask/app.py", line 1825, in full_dispatch_request
    rv = self.handle_user_exception(e)
  File "/home/creditapp/.local/lib/python3.13/site-packages/flask/app.py", line 1823, in full_dispatch_request
    rv = self.dispatch_request()
  File "/home/creditapp/.local/lib/python3.13/site-packages/flask/app.py", line 1799, in dispatch_request
    return self.ensure_sync(self.view_functions[rule.endpoint])(**view_args)
           ~~~~~~~~~~~~~~~~~~~~~~~~~~~~~~~~~~~~~~~~~~~~~~~~~~~~^^^^^^^^^^^^^
  File "/home/creditapp/.local/lib/python3.13/site-packages/flask_login/utils.py", line 290, in decorated_view
    return current_app.ensure_sync(func)(*args, **kwargs)
           ~~~~~~~~~~~~~~~~~~~~~~~~~~~~~^^^^^^^^^^^^^^^^^
  File "/home/creditapp/app/app_simple.py", line 424, in dashboard
    return render_template('admin/dashboard.html',
                          total_clientes=total_clientes,
    ...<2 lines>...
                          creditos_recientes=creditos_recientes,
                          abonos_recientes=abonos_recientes)
  File "/home/creditapp/.local/lib/python3.13/site-packages/flask/templating.py", line 146, in render_template
    template = app.jinja_env.get_or_select_template(template_name_or_list)
  File "/usr/local/lib/python3.13/site-packages/jinja2/environment.py", line 1084, in get_or_select_template
    return self.get_template(template_name_or_list, parent, globals)
           ~~~~~~~~~~~~~~~~~^^^^^^^^^^^^^^^^^^^^^^^^^^^^^^^^^^^^^^^^
  File "/usr/local/lib/python3.13/site-packages/jinja2/environment.py", line 1013, in get_template
    return self._load_template(name, globals)
           ~~~~~~~~~~~~~~~~~~~^^^^^^^^^^^^^^^
  File "/usr/local/lib/python3.13/site-packages/jinja2/environment.py", line 972, in _load_template
    template = self.loader.load(self, name, self.make_globals(globals))
  File "/usr/local/lib/python3.13/site-packages/jinja2/loaders.py", line 126, in load
    source, filename, uptodate = self.get_source(environment, name)
                                 ~~~~~~~~~~~~~~~^^^^^^^^^^^^^^^^^^^
  File "/home/creditapp/.local/lib/python3.13/site-packages/flask/templating.py", line 62, in get_source
    return self._get_source_fast(environment, template)
           ~~~~~~~~~~~~~~~~~~~~~^^^^^^^^^^^^^^^^^^^^^^^
  File "/home/creditapp/.local/lib/python3.13/site-packages/flask/templating.py", line 98, in _get_source_fast
2025-04-27 00:30:24,616: Exception on / [GET]
Traceback (most recent call last):
  File "/home/creditapp/.local/lib/python3.13/site-packages/flask/app.py", line 2528, in wsgi_app
    response = self.full_dispatch_request()
  File "/home/creditapp/.local/lib/python3.13/site-packages/flask/app.py", line 1825, in full_dispatch_request
    rv = self.handle_user_exception(e)
  File "/home/creditapp/.local/lib/python3.13/site-packages/flask/app.py", line 1823, in full_dispatch_request
    rv = self.dispatch_request()
  File "/home/creditapp/.local/lib/python3.13/site-packages/flask/app.py", line 1799, in dispatch_request
    return self.ensure_sync(self.view_functions[rule.endpoint])(**view_args)
           ~~~~~~~~~~~~~~~~~~~~~~~~~~~~~~~~~~~~~~~~~~~~~~~~~~~~^^^^^^^^^^^^^
  File "/home/creditapp/.local/lib/python3.13/site-packages/flask_login/utils.py", line 290, in decorated_view
    return current_app.ensure_sync(func)(*args, **kwargs)
           ~~~~~~~~~~~~~~~~~~~~~~~~~~~~~^^^^^^^^^^^^^^^^^
  File "/home/creditapp/app/app_simple.py", line 424, in dashboard
    return render_template('admin/dashboard.html',
                          total_clientes=total_clientes,
    ...<2 lines>...
                          creditos_recientes=creditos_recientes,
                          abonos_recientes=abonos_recientes)
  File "/home/creditapp/.local/lib/python3.13/site-packages/flask/templating.py", line 146, in render_template
    template = app.jinja_env.get_or_select_template(template_name_or_list)
  File "/usr/local/lib/python3.13/site-packages/jinja2/environment.py", line 1084, in get_or_select_template
    return self.get_template(template_name_or_list, parent, globals)
           ~~~~~~~~~~~~~~~~~^^^^^^^^^^^^^^^^^^^^^^^^^^^^^^^^^^^^^^^^
  File "/usr/local/lib/python3.13/site-packages/jinja2/environment.py", line 1013, in get_template
    return self._load_template(name, globals)
           ~~~~~~~~~~~~~~~~~~~^^^^^^^^^^^^^^^
  File "/usr/local/lib/python3.13/site-packages/jinja2/environment.py", line 972, in _load_template
    template = self.loader.load(self, name, self.make_globals(globals))
  File "/usr/local/lib/python3.13/site-packages/jinja2/loaders.py", line 126, in load
    source, filename, uptodate = self.get_source(environment, name)
                                 ~~~~~~~~~~~~~~~^^^^^^^^^^^^^^^^^^^
  File "/home/creditapp/.local/lib/python3.13/site-packages/flask/templating.py", line 62, in get_source
    return self._get_source_fast(environment, template)
           ~~~~~~~~~~~~~~~~~~~~~^^^^^^^^^^^^^^^^^^^^^^^
  File "/home/creditapp/.local/lib/python3.13/site-packages/flask/templating.py", line 98, in _get_source_fast
    raise TemplateNotFound(template)
jinja2.exceptions.TemplateNotFound: admin/dashboard.html
2025-04-27 00:30:35,135: Exception on / [GET]
Traceback (most recent call last):
  File "/home/creditapp/.local/lib/python3.13/site-packages/flask/app.py", line 2528, in wsgi_app
    response = self.full_dispatch_request()
  File "/home/creditapp/.local/lib/python3.13/site-packages/flask/app.py", line 1825, in full_dispatch_request
    rv = self.handle_user_exception(e)
  File "/home/creditapp/.local/lib/python3.13/site-packages/flask/app.py", line 1823, in full_dispatch_request
    rv = self.dispatch_request()
  File "/home/creditapp/.local/lib/python3.13/site-packages/flask/app.py", line 1799, in dispatch_request
    return self.ensure_sync(self.view_functions[rule.endpoint])(**view_args)
           ~~~~~~~~~~~~~~~~~~~~~~~~~~~~~~~~~~~~~~~~~~~~~~~~~~~~^^^^^^^^^^^^^
  File "/home/creditapp/.local/lib/python3.13/site-packages/flask_login/utils.py", line 290, in decorated_view
    return current_app.ensure_sync(func)(*args, **kwargs)
           ~~~~~~~~~~~~~~~~~~~~~~~~~~~~~^^^^^^^^^^^^^^^^^
  File "/home/creditapp/app/app_simple.py", line 424, in dashboard
    return render_template('admin/dashboard.html',
                          total_clientes=total_clientes,
    ...<2 lines>...
                          creditos_recientes=creditos_recientes,
                          abonos_recientes=abonos_recientes)
  File "/home/creditapp/.local/lib/python3.13/site-packages/flask/templating.py", line 146, in render_template
    template = app.jinja_env.get_or_select_template(template_name_or_list)
  File "/usr/local/lib/python3.13/site-packages/jinja2/environment.py", line 1084, in get_or_select_template
    return self.get_template(template_name_or_list, parent, globals)
           ~~~~~~~~~~~~~~~~~^^^^^^^^^^^^^^^^^^^^^^^^^^^^^^^^^^^^^^^^
  File "/usr/local/lib/python3.13/site-packages/jinja2/environment.py", line 1013, in get_template
    return self._load_template(name, globals)
           ~~~~~~~~~~~~~~~~~~~^^^^^^^^^^^^^^^
  File "/usr/local/lib/python3.13/site-packages/jinja2/environment.py", line 972, in _load_template
    template = self.loader.load(self, name, self.make_globals(globals))
  File "/usr/local/lib/python3.13/site-packages/jinja2/loaders.py", line 126, in load
    source, filename, uptodate = self.get_source(environment, name)
                                 ~~~~~~~~~~~~~~~^^^^^^^^^^^^^^^^^^^
  File "/home/creditapp/.local/lib/python3.13/site-packages/flask/templating.py", line 62, in get_source
    return self._get_source_fast(environment, template)
           ~~~~~~~~~~~~~~~~~~~~~^^^^^^^^^^^^^^^^^^^^^^^
  File "/home/creditapp/.local/lib/python3.13/site-packages/flask/templating.py", line 98, in _get_source_fast
    raise TemplateNotFound(template)
jinja2.exceptions.TemplateNotFound: admin/dashboard.html
2025-04-27 00:36:06,026: Exception on / [GET]
Traceback (most recent call last):
  File "/home/creditapp/.local/lib/python3.13/site-packages/flask/app.py", line 2528, in wsgi_app
    response = self.full_dispatch_request()
  File "/home/creditapp/.local/lib/python3.13/site-packages/flask/app.py", line 1825, in full_dispatch_request
    rv = self.handle_user_exception(e)
  File "/home/creditapp/.local/lib/python3.13/site-packages/flask/app.py", line 1823, in full_dispatch_request
    rv = self.dispatch_request()
  File "/home/creditapp/.local/lib/python3.13/site-packages/flask/app.py", line 1799, in dispatch_request
    return self.ensure_sync(self.view_functions[rule.endpoint])(**view_args)
           ~~~~~~~~~~~~~~~~~~~~~~~~~~~~~~~~~~~~~~~~~~~~~~~~~~~~^^^^^^^^^^^^^
  File "/home/creditapp/.local/lib/python3.13/site-packages/flask_login/utils.py", line 290, in decorated_view
    return render_template('admin/dashboard.html',
                          total_clientes=total_clientes,
    ...<2 lines>...
                          creditos_recientes=creditos_recientes,
                          abonos_recientes=abonos_recientes)
  File "/home/creditapp/.local/lib/python3.13/site-packages/flask/templating.py", line 146, in render_template
    template = app.jinja_env.get_or_select_template(template_name_or_list)
  File "/usr/local/lib/python3.13/site-packages/jinja2/environment.py", line 1084, in get_or_select_template
    return self.get_template(template_name_or_list, parent, globals)
           ~~~~~~~~~~~~~~~~~^^^^^^^^^^^^^^^^^^^^^^^^^^^^^^^^^^^^^^^^
  File "/usr/local/lib/python3.13/site-packages/jinja2/environment.py", line 1013, in get_template
    return self._load_template(name, globals)
           ~~~~~~~~~~~~~~~~~~~^^^^^^^^^^^^^^^
  File "/usr/local/lib/python3.13/site-packages/jinja2/environment.py", line 972, in _load_template
    template = self.loader.load(self, name, self.make_globals(globals))
  File "/usr/local/lib/python3.13/site-packages/jinja2/loaders.py", line 126, in load
    source, filename, uptodate = self.get_source(environment, name)
                                 ~~~~~~~~~~~~~~~^^^^^^^^^^^^^^^^^^^
  File "/home/creditapp/.local/lib/python3.13/site-packages/flask/templating.py", line 62, in get_source
    return self._get_source_fast(environment, template)
           ~~~~~~~~~~~~~~~~~~~~~^^^^^^^^^^^^^^^^^^^^^^^
  File "/home/creditapp/.local/lib/python3.13/site-packages/flask/templating.py", line 98, in _get_source_fast
2025-04-27 00:36:58,321: Exception on / [GET]
Traceback (most recent call last):
  File "/home/creditapp/.local/lib/python3.13/site-packages/flask/app.py", line 2528, in wsgi_app
    response = self.full_dispatch_request()
  File "/home/creditapp/.local/lib/python3.13/site-packages/flask/app.py", line 1825, in full_dispatch_request
    rv = self.handle_user_exception(e)
  File "/home/creditapp/.local/lib/python3.13/site-packages/flask/app.py", line 1823, in full_dispatch_request
    rv = self.dispatch_request()
  File "/home/creditapp/.local/lib/python3.13/site-packages/flask/app.py", line 1799, in dispatch_request
    return self.ensure_sync(self.view_functions[rule.endpoint])(**view_args)
           ~~~~~~~~~~~~~~~~~~~~~~~~~~~~~~~~~~~~~~~~~~~~~~~~~~~~^^^^^^^^^^^^^
  File "/home/creditapp/.local/lib/python3.13/site-packages/flask_login/utils.py", line 290, in decorated_view
    return current_app.ensure_sync(func)(*args, **kwargs)
           ~~~~~~~~~~~~~~~~~~~~~~~~~~~~~^^^^^^^^^^^^^^^^^
  File "/home/creditapp/app/app_simple.py", line 424, in dashboard
    return render_template('admin/dashboard.html',
                          total_clientes=total_clientes,
    ...<2 lines>...
                          creditos_recientes=creditos_recientes,
                          abonos_recientes=abonos_recientes)
  File "/home/creditapp/.local/lib/python3.13/site-packages/flask/templating.py", line 146, in render_template
    template = app.jinja_env.get_or_select_template(template_name_or_list)
  File "/usr/local/lib/python3.13/site-packages/jinja2/environment.py", line 1084, in get_or_select_template
    return self.get_template(template_name_or_list, parent, globals)
           ~~~~~~~~~~~~~~~~~^^^^^^^^^^^^^^^^^^^^^^^^^^^^^^^^^^^^^^^^
  File "/usr/local/lib/python3.13/site-packages/jinja2/environment.py", line 1013, in get_template
    return self._load_template(name, globals)
    template = self.loader.load(self, name, self.make_globals(globals))
  File "/usr/local/lib/python3.13/site-packages/jinja2/loaders.py", line 126, in load
    source, filename, uptodate = self.get_source(environment, name)
                                 ~~~~~~~~~~~~~~~^^^^^^^^^^^^^^^^^^^
  File "/home/creditapp/.local/lib/python3.13/site-packages/flask/templating.py", line 62, in get_source
    return self._get_source_fast(environment, template)
           ~~~~~~~~~~~~~~~~~~~~~^^^^^^^^^^^^^^^^^^^^^^^
  File "/home/creditapp/.local/lib/python3.13/site-packages/flask/templating.py", line 98, in _get_source_fast
    raise TemplateNotFound(template)
jinja2.exceptions.TemplateNotFound: admin/dashboard.html
2025-04-27 00:37:16,422: Exception on / [GET]
Traceback (most recent call last):
  File "/home/creditapp/.local/lib/python3.13/site-packages/flask/app.py", line 2528, in wsgi_app
    response = self.full_dispatch_request()
  File "/home/creditapp/.local/lib/python3.13/site-packages/flask/app.py", line 1825, in full_dispatch_request
    rv = self.handle_user_exception(e)
  File "/home/creditapp/.local/lib/python3.13/site-packages/flask/app.py", line 1823, in full_dispatch_request
    rv = self.dispatch_request()
  File "/home/creditapp/.local/lib/python3.13/site-packages/flask/app.py", line 1799, in dispatch_request
    return self.ensure_sync(self.view_functions[rule.endpoint])(**view_args)
           ~~~~~~~~~~~~~~~~~~~~~~~~~~~~~~~~~~~~~~~~~~~~~~~~~~~~^^^^^^^^^^^^^
  File "/home/creditapp/.local/lib/python3.13/site-packages/flask_login/utils.py", line 290, in decorated_view
    return current_app.ensure_sync(func)(*args, **kwargs)
           ~~~~~~~~~~~~~~~~~~~~~~~~~~~~~^^^^^^^^^^^^^^^^^
  File "/home/creditapp/app/app_simple.py", line 424, in dashboard
    return render_template('admin/dashboard.html',
                          total_clientes=total_clientes,
    ...<2 lines>...
                          creditos_recientes=creditos_recientes,
                          abonos_recientes=abonos_recientes)
  File "/home/creditapp/.local/lib/python3.13/site-packages/flask/templating.py", line 146, in render_template
    template = app.jinja_env.get_or_select_template(template_name_or_list)
  File "/usr/local/lib/python3.13/site-packages/jinja2/environment.py", line 1084, in get_or_select_template
    return self.get_template(template_name_or_list, parent, globals)
           ~~~~~~~~~~~~~~~~~^^^^^^^^^^^^^^^^^^^^^^^^^^^^^^^^^^^^^^^^
  File "/usr/local/lib/python3.13/site-packages/jinja2/environment.py", line 1013, in get_template
    return self._load_template(name, globals)
           ~~~~~~~~~~~~~~~~~~~^^^^^^^^^^^^^^^
  File "/usr/local/lib/python3.13/site-packages/jinja2/environment.py", line 972, in _load_template
    template = self.loader.load(self, name, self.make_globals(globals))
  File "/usr/local/lib/python3.13/site-packages/jinja2/loaders.py", line 126, in load
    source, filename, uptodate = self.get_source(environment, name)
                                 ~~~~~~~~~~~~~~~^^^^^^^^^^^^^^^^^^^
  File "/home/creditapp/.local/lib/python3.13/site-packages/flask/templating.py", line 62, in get_source
    return self._get_source_fast(environment, template)
           ~~~~~~~~~~~~~~~~~~~~~^^^^^^^^^^^^^^^^^^^^^^^
  File "/home/creditapp/.local/lib/python3.13/site-packages/flask/templating.py", line 98, in _get_source_fast
    raise TemplateNotFound(template)
  File "/home/creditapp/.local/lib/python3.13/site-packages/flask/app.py", line 1825, in full_dispatch_request
    rv = self.handle_user_exception(e)
  File "/home/creditapp/.local/lib/python3.13/site-packages/flask/app.py", line 1823, in full_dispatch_request
    rv = self.dispatch_request()
  File "/home/creditapp/.local/lib/python3.13/site-packages/flask/app.py", line 1799, in dispatch_request
    return self.ensure_sync(self.view_functions[rule.endpoint])(**view_args)
           ~~~~~~~~~~~~~~~~~~~~~~~~~~~~~~~~~~~~~~~~~~~~~~~~~~~~^^^^^^^^^^^^^
  File "/home/creditapp/.local/lib/python3.13/site-packages/flask_login/utils.py", line 290, in decorated_view
    return current_app.ensure_sync(func)(*args, **kwargs)
           ~~~~~~~~~~~~~~~~~~~~~~~~~~~~~^^^^^^^^^^^^^^^^^
  File "/home/creditapp/.local/lib/python3.13/site-packages/flask/templating.py", line 146, in render_template
    template = app.jinja_env.get_or_select_template(template_name_or_list)
  File "/usr/local/lib/python3.13/site-packages/jinja2/environment.py", line 1084, in get_or_select_template
    return self.get_template(template_name_or_list, parent, globals)
           ~~~~~~~~~~~~~~~~~^^^^^^^^^^^^^^^^^^^^^^^^^^^^^^^^^^^^^^^^
  File "/usr/local/lib/python3.13/site-packages/jinja2/environment.py", line 1013, in get_template
    return self._load_template(name, globals)
           ~~~~~~~~~~~~~~~~~~~^^^^^^^^^^^^^^^
  File "/usr/local/lib/python3.13/site-packages/jinja2/environment.py", line 972, in _load_template
    template = self.loader.load(self, name, self.make_globals(globals))
  File "/usr/local/lib/python3.13/site-packages/jinja2/loaders.py", line 126, in load
    source, filename, uptodate = self.get_source(environment, name)
                                 ~~~~~~~~~~~~~~~^^^^^^^^^^^^^^^^^^^
  File "/home/creditapp/.local/lib/python3.13/site-packages/flask/templating.py", line 62, in get_source
    return self._get_source_fast(environment, template)
           ~~~~~~~~~~~~~~~~~~~~~^^^^^^^^^^^^^^^^^^^^^^^
  File "/home/creditapp/.local/lib/python3.13/site-packages/flask/templating.py", line 98, in _get_source_fast
    raise TemplateNotFound(template)
jinja2.exceptions.TemplateNotFound: admin/dashboard.html
2025-04-27 00:52:22,954: Exception on /clientes [GET]
Traceback (most recent call last):
  File "/home/creditapp/.local/lib/python3.13/site-packages/flask/app.py", line 2528, in wsgi_app
    response = self.full_dispatch_request()
  File "/home/creditapp/.local/lib/python3.13/site-packages/flask/app.py", line 1825, in full_dispatch_request
    rv = self.handle_user_exception(e)
  File "/home/creditapp/.local/lib/python3.13/site-packages/flask/app.py", line 1823, in full_dispatch_request
    rv = self.dispatch_request()
  File "/home/creditapp/.local/lib/python3.13/site-packages/flask/app.py", line 1799, in dispatch_request
    return self.ensure_sync(self.view_functions[rule.endpoint])(**view_args)
           ~~~~~~~~~~~~~~~~~~~~~~~~~~~~~~~~~~~~~~~~~~~~~~~~~~~~^^^^^^^^^^^^^
  File "/home/creditapp/.local/lib/python3.13/site-packages/flask_login/utils.py", line 290, in decorated_view
    return current_app.ensure_sync(func)(*args, **kwargs)
           ~~~~~~~~~~~~~~~~~~~~~~~~~~~~~^^^^^^^^^^^^^^^^^
  File "/home/creditapp/app/app_simple.py", line 574, in clientes
    return render_template('clientes/lista.html', clientes=clientes)
  File "/home/creditapp/.local/lib/python3.13/site-packages/flask/templating.py", line 146, in render_template
    template = app.jinja_env.get_or_select_template(template_name_or_list)
  File "/usr/local/lib/python3.13/site-packages/jinja2/environment.py", line 1013, in get_template
    return self._load_template(name, globals)
           ~~~~~~~~~~~~~~~~~~~^^^^^^^^^^^^^^^
  File "/usr/local/lib/python3.13/site-packages/jinja2/environment.py", line 972, in _load_template
    template = self.loader.load(self, name, self.make_globals(globals))
  File "/usr/local/lib/python3.13/site-packages/jinja2/loaders.py", line 126, in load
    source, filename, uptodate = self.get_source(environment, name)
                                 ~~~~~~~~~~~~~~~^^^^^^^^^^^^^^^^^^^
  File "/home/creditapp/.local/lib/python3.13/site-packages/flask/templating.py", line 62, in get_source
    return self._get_source_fast(environment, template)
           ~~~~~~~~~~~~~~~~~~~~~^^^^^^^^^^^^^^^^^^^^^^^
  File "/home/creditapp/.local/lib/python3.13/site-packages/flask/templating.py", line 98, in _get_source_fast
    raise TemplateNotFound(template)
jinja2.exceptions.TemplateNotFound: clientes/lista.html
2025-04-27 12:44:07,400: OSError: write error
2025-04-27 13:25:37,917: Exception on /finanzas/comisiones [GET]
Traceback (most recent call last):
  File "/home/creditapp/.local/lib/python3.13/site-packages/flask/app.py", line 2528, in wsgi_app
    response = self.full_dispatch_request()
           ~~~~~~~~~~~~~~~~~~~~~~~~~~~~~^^^^^^^^^^^^^^^^^
  File "/home/creditapp/app/app_simple.py", line 313, in decorated_function
    return f(*args, **kwargs)
  File "/home/creditapp/app/templates/admin/dashboard.html", line 186, in top-level template code
    {% block content %}{% endblock %}
    ^^^^^^^^^
    ^^^^^^^^^^^^^^^^^^^^
  File "/usr/local/lib/python3.13/site-packages/jinja2/environment.py", line 487, in getattr
    return getattr(obj, attribute)
jinja2.exceptions.UndefinedError: 'now' is undefined
2025-04-27 13:25:43,359: Exception on /finanzas/comisiones [GET]
Traceback (most recent call last):
  File "/home/creditapp/.local/lib/python3.13/site-packages/flask/app.py", line 2528, in wsgi_app
    response = self.full_dispatch_request()
  File "/home/creditapp/.local/lib/python3.13/site-packages/flask/app.py", line 1825, in full_dispatch_request
    rv = self.handle_user_exception(e)
  File "/home/creditapp/.local/lib/python3.13/site-packages/flask/app.py", line 1823, in full_dispatch_request
    rv = self.dispatch_request()
  File "/home/creditapp/.local/lib/python3.13/site-packages/flask/app.py", line 1799, in dispatch_request
    return self.ensure_sync(self.view_functions[rule.endpoint])(**view_args)
           ~~~~~~~~~~~~~~~~~~~~~~~~~~~~~~~~~~~~~~~~~~~~~~~~~~~~^^^^^^^^^^^^^
  File "/home/creditapp/.local/lib/python3.13/site-packages/flask_login/utils.py", line 290, in decorated_view
    return current_app.ensure_sync(func)(*args, **kwargs)
           ~~~~~~~~~~~~~~~~~~~~~~~~~~~~~^^^^^^^^^^^^^^^^^
  File "/home/creditapp/app/app_simple.py", line 313, in decorated_function
    return f(*args, **kwargs)
  File "/home/creditapp/app/app_simple.py", line 1289, in comisiones
    return render_template('finanzas/comisiones.html',
                          comisiones=comisiones_data,
                          vendedores=vendedores_lista,
                          periodo=periodo,
                          inicio_periodo=inicio_periodo)
  File "/home/creditapp/.local/lib/python3.13/site-packages/flask/templating.py", line 147, in render_template
    return _render(app, template, context)
  File "/home/creditapp/.local/lib/python3.13/site-packages/flask/templating.py", line 130, in _render
    rv = template.render(context)
  File "/usr/local/lib/python3.13/site-packages/jinja2/environment.py", line 1304, in render
    self.environment.handle_exception()
    ~~~~~~~~~~~~~~~~~~~~~~~~~~~~~~~~~^^
  File "/usr/local/lib/python3.13/site-packages/jinja2/environment.py", line 939, in handle_exception
    raise rewrite_traceback_stack(source=source)
  File "/home/creditapp/app/templates/finanzas/comisiones.html", line 1, in top-level template code
    {% extends 'admin/dashboard.html' %}
    ^^^^^^^^^^^^^^^^^^^^^^^^^
  File "/home/creditapp/app/templates/admin/dashboard.html", line 186, in top-level template code
    {% block content %}{% endblock %}
    ^^^^^^^^^
  File "/home/creditapp/app/templates/finanzas/comisiones.html", line 43, in block 'content'
    <strong>Período actual:</strong> Desde {{ inicio_periodo.strftime('%d/%m/%Y') }} hasta {{ now.strftime('%d/%m/%Y') }}
    ^^^^^^^^^^^^^^^^^^^^
  File "/usr/local/lib/python3.13/site-packages/jinja2/environment.py", line 487, in getattr
    return getattr(obj, attribute)
jinja2.exceptions.UndefinedError: 'now' is undefined
2025-04-27 13:26:56,287: Exception on /finanzas/comisiones [GET]
Traceback (most recent call last):
  File "/home/creditapp/.local/lib/python3.13/site-packages/flask/app.py", line 2528, in wsgi_app
    response = self.full_dispatch_request()
  File "/home/creditapp/.local/lib/python3.13/site-packages/flask/app.py", line 1825, in full_dispatch_request
    rv = self.handle_user_exception(e)
  File "/home/creditapp/.local/lib/python3.13/site-packages/flask/app.py", line 1823, in full_dispatch_request
    rv = self.dispatch_request()
  File "/home/creditapp/.local/lib/python3.13/site-packages/flask/app.py", line 1799, in dispatch_request
    return self.ensure_sync(self.view_functions[rule.endpoint])(**view_args)
           ~~~~~~~~~~~~~~~~~~~~~~~~~~~~~~~~~~~~~~~~~~~~~~~~~~~~^^^^^^^^^^^^^
  File "/home/creditapp/.local/lib/python3.13/site-packages/flask_login/utils.py", line 290, in decorated_view
    return current_app.ensure_sync(func)(*args, **kwargs)
           ~~~~~~~~~~~~~~~~~~~~~~~~~~~~~^^^^^^^^^^^^^^^^^
  File "/home/creditapp/app/app_simple.py", line 313, in decorated_function
    return f(*args, **kwargs)
  File "/home/creditapp/app/app_simple.py", line 1289, in comisiones
    return render_template('finanzas/comisiones.html',
                          comisiones=comisiones_data,
                          vendedores=vendedores_lista,
                          periodo=periodo,
                          inicio_periodo=inicio_periodo)
    return _render(app, template, context)
    rv = template.render(context)
  File "/usr/local/lib/python3.13/site-packages/jinja2/environment.py", line 1304, in render
    self.environment.handle_exception()
    ~~~~~~~~~~~~~~~~~~~~~~~~~~~~~~~~~^^
  File "/usr/local/lib/python3.13/site-packages/jinja2/environment.py", line 939, in handle_exception
    raise rewrite_traceback_stack(source=source)
    {% extends 'admin/dashboard.html' %}
    ^^^^^^^^^^^^^^^^^^^^^^^^^
  File "/home/creditapp/app/templates/admin/dashboard.html", line 186, in top-level template code
    {% block content %}{% endblock %}
    ^^^^^^^^^
  File "/home/creditapp/app/templates/finanzas/comisiones.html", line 43, in block 'content'
    <strong>Período actual:</strong> Desde {{ inicio_periodo.strftime('%d/%m/%Y') }} hasta {{ now.strftime('%d/%m/%Y') }}
    ^^^^^^^^^^^^^^^^^^^^
jinja2.exceptions.UndefinedError: 'now' is undefined
2025-04-27 13:27:14,958: Exception on /usuarios [GET]
Traceback (most recent call last):
  File "/home/creditapp/.local/lib/python3.13/site-packages/flask/app.py", line 2528, in wsgi_app
    response = self.full_dispatch_request()
  File "/home/creditapp/.local/lib/python3.13/site-packages/flask/app.py", line 1825, in full_dispatch_request
    rv = self.handle_user_exception(e)
  File "/home/creditapp/.local/lib/python3.13/site-packages/flask/app.py", line 1823, in full_dispatch_request
    rv = self.dispatch_request()
  File "/home/creditapp/.local/lib/python3.13/site-packages/flask/app.py", line 1799, in dispatch_request
    return self.ensure_sync(self.view_functions[rule.endpoint])(**view_args)
           ~~~~~~~~~~~~~~~~~~~~~~~~~~~~~~~~~~~~~~~~~~~~~~~~~~~~^^^^^^^^^^^^^
  File "/home/creditapp/.local/lib/python3.13/site-packages/flask_login/utils.py", line 290, in decorated_view
    return current_app.ensure_sync(func)(*args, **kwargs)
           ~~~~~~~~~~~~~~~~~~~~~~~~~~~~~^^^^^^^^^^^^^^^^^
  File "/home/creditapp/app/app_simple.py", line 313, in decorated_function
    return f(*args, **kwargs)
  File "/home/creditapp/app/app_simple.py", line 436, in usuarios
    return render_template('admin/usuarios.html', usuarios=usuarios)
  File "/home/creditapp/.local/lib/python3.13/site-packages/flask/templating.py", line 146, in render_template
    template = app.jinja_env.get_or_select_template(template_name_or_list)
  File "/usr/local/lib/python3.13/site-packages/jinja2/environment.py", line 1084, in get_or_select_template
    return self.get_template(template_name_or_list, parent, globals)
           ~~~~~~~~~~~~~~~~~^^^^^^^^^^^^^^^^^^^^^^^^^^^^^^^^^^^^^^^^
  File "/usr/local/lib/python3.13/site-packages/jinja2/environment.py", line 1013, in get_template
    return self._load_template(name, globals)
           ~~~~~~~~~~~~~~~~~~~^^^^^^^^^^^^^^^
  File "/usr/local/lib/python3.13/site-packages/jinja2/environment.py", line 972, in _load_template
    template = self.loader.load(self, name, self.make_globals(globals))
  File "/usr/local/lib/python3.13/site-packages/jinja2/loaders.py", line 126, in load
    source, filename, uptodate = self.get_source(environment, name)
                                 ~~~~~~~~~~~~~~~^^^^^^^^^^^^^^^^^^^
  File "/home/creditapp/.local/lib/python3.13/site-packages/flask/templating.py", line 62, in get_source
    return self._get_source_fast(environment, template)
           ~~~~~~~~~~~~~~~~~~~~~^^^^^^^^^^^^^^^^^^^^^^^
  File "/home/creditapp/.local/lib/python3.13/site-packages/flask/templating.py", line 98, in _get_source_fast
    raise TemplateNotFound(template)
jinja2.exceptions.TemplateNotFound: admin/usuarios.html
2025-04-27 19:26:52,024: Exception on / [GET]
Traceback (most recent call last):
  File "/home/creditapp/.local/lib/python3.13/site-packages/flask/app.py", line 2528, in wsgi_app
    response = self.full_dispatch_request()
  File "/home/creditapp/.local/lib/python3.13/site-packages/flask/app.py", line 1825, in full_dispatch_request
    rv = self.handle_user_exception(e)
  File "/home/creditapp/.local/lib/python3.13/site-packages/flask/app.py", line 1823, in full_dispatch_request
    rv = self.dispatch_request()
  File "/home/creditapp/.local/lib/python3.13/site-packages/flask/app.py", line 1799, in dispatch_request
    return self.ensure_sync(self.view_functions[rule.endpoint])(**view_args)
           ~~~~~~~~~~~~~~~~~~~~~~~~~~~~~~~~~~~~~~~~~~~~~~~~~~~~^^^^^^^^^^^^^
  File "/home/creditapp/.local/lib/python3.13/site-packages/flask_login/utils.py", line 290, in decorated_view
    return current_app.ensure_sync(func)(*args, **kwargs)
           ~~~~~~~~~~~~~~~~~~~~~~~~~~~~~^^^^^^^^^^^^^^^^^
  File "/home/creditapp/app/app_simple.py", line 420, in dashboard
    total_por_cobrar = db.session.query(func.sum(Credito.saldo)).filter(Credito.estado == 'Pendiente').scalar() or 0
                                        ^^^^
NameError: name 'func' is not defined
2025-04-27 19:27:04,052: Exception on / [GET]
Traceback (most recent call last):
  File "/home/creditapp/.local/lib/python3.13/site-packages/flask/app.py", line 2528, in wsgi_app
    response = self.full_dispatch_request()
  File "/home/creditapp/.local/lib/python3.13/site-packages/flask/app.py", line 1825, in full_dispatch_request
    rv = self.handle_user_exception(e)
  File "/home/creditapp/.local/lib/python3.13/site-packages/flask/app.py", line 1823, in full_dispatch_request
    rv = self.dispatch_request()
  File "/home/creditapp/.local/lib/python3.13/site-packages/flask/app.py", line 1799, in dispatch_request
    return self.ensure_sync(self.view_functions[rule.endpoint])(**view_args)
           ~~~~~~~~~~~~~~~~~~~~~~~~~~~~~~~~~~~~~~~~~~~~~~~~~~~~^^^^^^^^^^^^^
  File "/home/creditapp/.local/lib/python3.13/site-packages/flask_login/utils.py", line 290, in decorated_view
    return current_app.ensure_sync(func)(*args, **kwargs)
           ~~~~~~~~~~~~~~~~~~~~~~~~~~~~~^^^^^^^^^^^^^^^^^
  File "/home/creditapp/app/app_simple.py", line 420, in dashboard
    total_por_cobrar = db.session.query(func.sum(Credito.saldo)).filter(Credito.estado == 'Pendiente').scalar() or 0
                                        ^^^^
NameError: name 'func' is not defined
2025-04-27 21:36:05,359: Error running WSGI application
2025-04-27 21:36:05,389: RuntimeError: Either 'SQLALCHEMY_DATABASE_URI' or 'SQLALCHEMY_BINDS' must be set.
2025-04-27 21:36:05,389:   File "/var/www/creditapp_pythonanywhere_com_wsgi.py", line 10, in <module>
2025-04-27 21:36:05,390:     from app_simple import app as application
2025-04-27 21:36:05,390: 
2025-04-27 21:36:05,390:   File "/home/creditapp/app/app_simple.py", line 17, in <module>
2025-04-27 21:36:05,390:     db = SQLAlchemy(app)
2025-04-27 21:36:05,390: 
2025-04-27 21:36:05,391:   File "/home/creditapp/.local/lib/python3.13/site-packages/flask_sqlalchemy/extension.py", line 219, in __init__
2025-04-27 21:36:05,391:     self.init_app(app)
2025-04-27 21:36:05,391:     ~~~~~~~~~~~~~^^^^^
2025-04-27 21:36:05,391: 
2025-04-27 21:36:05,391:   File "/home/creditapp/.local/lib/python3.13/site-packages/flask_sqlalchemy/extension.py", line 307, in init_app
2025-04-27 21:36:05,391:     raise RuntimeError(
2025-04-27 21:36:05,391:         "Either 'SQLALCHEMY_DATABASE_URI' or 'SQLALCHEMY_BINDS' must be set."
2025-04-27 21:36:05,392:     )
2025-04-27 21:36:05,392: ***************************************************
2025-04-27 21:36:05,392: If you're seeing an import error and don't know why,
2025-04-27 21:36:05,392: we have a dedicated help page to help you debug: 
2025-04-27 21:36:05,392: https://help.pythonanywhere.com/pages/DebuggingImportError/
2025-04-27 21:36:05,392: ***************************************************
2025-04-27 21:36:42,289: Error running WSGI application
2025-04-27 21:36:42,293: RuntimeError: Either 'SQLALCHEMY_DATABASE_URI' or 'SQLALCHEMY_BINDS' must be set.
2025-04-27 21:36:42,294:   File "/var/www/creditapp_pythonanywhere_com_wsgi.py", line 10, in <module>
2025-04-27 21:36:42,294:     from app_simple import app as application
2025-04-27 21:36:42,294: 
2025-04-27 21:36:42,295:   File "/home/creditapp/.local/lib/python3.13/site-packages/flask_sqlalchemy/extension.py", line 219, in __init__
2025-04-27 21:36:42,295:     self.init_app(app)
2025-04-27 21:36:42,296:     raise RuntimeError(
2025-04-27 21:36:42,297:         "Either 'SQLALCHEMY_DATABASE_URI' or 'SQLALCHEMY_BINDS' must be set."
2025-04-27 21:36:42,297:     )
2025-04-27 21:36:42,297: ***************************************************
2025-04-27 21:36:42,297: If you're seeing an import error and don't know why,
2025-04-27 21:36:42,298: https://help.pythonanywhere.com/pages/DebuggingImportError/
2025-04-27 21:36:42,298: ***************************************************
2025-04-27 22:01:25,880: Error running WSGI application
2025-04-27 23:21:22,181: Exception on /login [GET]
Traceback (most recent call last):
  File "/home/creditapp/.local/lib/python3.13/site-packages/flask/app.py", line 2528, in wsgi_app
    response = self.full_dispatch_request()
  File "/home/creditapp/.local/lib/python3.13/site-packages/flask/app.py", line 1825, in full_dispatch_request
    rv = self.handle_user_exception(e)
  File "/home/creditapp/.local/lib/python3.13/site-packages/flask/app.py", line 1823, in full_dispatch_request
    rv = self.dispatch_request()
  File "/home/creditapp/.local/lib/python3.13/site-packages/flask/app.py", line 1799, in dispatch_request
    return self.ensure_sync(self.view_functions[rule.endpoint])(**view_args)
           ~~~~~~~~~~~~~~~~~~~~~~~~~~~~~~~~~~~~~~~~~~~~~~~~~~~~^^^^^^^^^^^^^
  File "/home/creditapp/app/app_simple.py", line 157, in login
    return render_template('login.html')
  File "/home/creditapp/.local/lib/python3.13/site-packages/flask/templating.py", line 146, in render_template
    template = app.jinja_env.get_or_select_template(template_name_or_list)
  File "/usr/local/lib/python3.13/site-packages/jinja2/environment.py", line 1084, in get_or_select_template
    return self.get_template(template_name_or_list, parent, globals)
           ~~~~~~~~~~~~~~~~~^^^^^^^^^^^^^^^^^^^^^^^^^^^^^^^^^^^^^^^^
  File "/usr/local/lib/python3.13/site-packages/jinja2/environment.py", line 1013, in get_template
    return self._load_template(name, globals)
           ~~~~~~~~~~~~~~~~~~~^^^^^^^^^^^^^^^
  File "/usr/local/lib/python3.13/site-packages/jinja2/environment.py", line 972, in _load_template
    template = self.loader.load(self, name, self.make_globals(globals))
  File "/usr/local/lib/python3.13/site-packages/jinja2/loaders.py", line 126, in load
    source, filename, uptodate = self.get_source(environment, name)
                                 ~~~~~~~~~~~~~~~^^^^^^^^^^^^^^^^^^^
    return self._get_source_fast(environment, template)
           ~~~~~~~~~~~~~~~~~~~~~^^^^^^^^^^^^^^^^^^^^^^^
  File "/home/creditapp/.local/lib/python3.13/site-packages/flask/templating.py", line 98, in _get_source_fast
    raise TemplateNotFound(template)
jinja2.exceptions.TemplateNotFound: login.html
2025-04-28 00:11:40,927: Exception on /login [GET]
Traceback (most recent call last):
  File "/home/creditapp/.local/lib/python3.13/site-packages/flask/app.py", line 2528, in wsgi_app
    response = self.full_dispatch_request()
  File "/home/creditapp/.local/lib/python3.13/site-packages/flask/app.py", line 1825, in full_dispatch_request
    rv = self.handle_user_exception(e)
  File "/home/creditapp/.local/lib/python3.13/site-packages/flask/app.py", line 1823, in full_dispatch_request
    rv = self.dispatch_request()
  File "/home/creditapp/.local/lib/python3.13/site-packages/flask/app.py", line 1799, in dispatch_request
    return self.ensure_sync(self.view_functions[rule.endpoint])(**view_args)
           ~~~~~~~~~~~~~~~~~~~~~~~~~~~~~~~~~~~~~~~~~~~~~~~~~~~~^^^^^^^^^^^^^
  File "/home/creditapp/app/app_simple.py", line 157, in login
    return render_template('login.html')
  File "/home/creditapp/.local/lib/python3.13/site-packages/flask/templating.py", line 146, in render_template
    template = app.jinja_env.get_or_select_template(template_name_or_list)
  File "/usr/local/lib/python3.13/site-packages/jinja2/environment.py", line 1084, in get_or_select_template
    return self.get_template(template_name_or_list, parent, globals)
           ~~~~~~~~~~~~~~~~~^^^^^^^^^^^^^^^^^^^^^^^^^^^^^^^^^^^^^^^^
  File "/usr/local/lib/python3.13/site-packages/jinja2/environment.py", line 1013, in get_template
    return self._load_template(name, globals)
           ~~~~~~~~~~~~~~~~~~~^^^^^^^^^^^^^^^
  File "/usr/local/lib/python3.13/site-packages/jinja2/environment.py", line 972, in _load_template
    template = self.loader.load(self, name, self.make_globals(globals))
  File "/usr/local/lib/python3.13/site-packages/jinja2/loaders.py", line 126, in load
    source, filename, uptodate = self.get_source(environment, name)
                                 ~~~~~~~~~~~~~~~^^^^^^^^^^^^^^^^^^^
  File "/home/creditapp/.local/lib/python3.13/site-packages/flask/templating.py", line 62, in get_source
  File "/home/creditapp/.local/lib/python3.13/site-packages/flask/templating.py", line 98, in _get_source_fast
    raise TemplateNotFound(template)
  File "/home/creditapp/app/app_simple.py", line 157, in login
    return render_template('login.html')
  File "/home/creditapp/.local/lib/python3.13/site-packages/flask/templating.py", line 146, in render_template
    template = app.jinja_env.get_or_select_template(template_name_or_list)
  File "/usr/local/lib/python3.13/site-packages/jinja2/environment.py", line 1084, in get_or_select_template
    return self.get_template(template_name_or_list, parent, globals)
           ~~~~~~~~~~~~~~~~~^^^^^^^^^^^^^^^^^^^^^^^^^^^^^^^^^^^^^^^^
  File "/usr/local/lib/python3.13/site-packages/jinja2/environment.py", line 1013, in get_template
    return self._load_template(name, globals)
           ~~~~~~~~~~~~~~~~~~~^^^^^^^^^^^^^^^
  File "/usr/local/lib/python3.13/site-packages/jinja2/environment.py", line 972, in _load_template
    template = self.loader.load(self, name, self.make_globals(globals))
  File "/usr/local/lib/python3.13/site-packages/jinja2/loaders.py", line 126, in load
    source, filename, uptodate = self.get_source(environment, name)
                                 ~~~~~~~~~~~~~~~^^^^^^^^^^^^^^^^^^^
  File "/home/creditapp/.local/lib/python3.13/site-packages/flask/templating.py", line 62, in get_source
    return self._get_source_fast(environment, template)
           ~~~~~~~~~~~~~~~~~~~~~^^^^^^^^^^^^^^^^^^^^^^^
  File "/home/creditapp/.local/lib/python3.13/site-packages/flask/templating.py", line 98, in _get_source_fast
    raise TemplateNotFound(template)
jinja2.exceptions.TemplateNotFound: login.html
2025-04-28 19:07:02,978: Exception on /login [GET]
Traceback (most recent call last):
  File "/home/creditapp/.local/lib/python3.13/site-packages/flask/app.py", line 2528, in wsgi_app
    response = self.full_dispatch_request()
  File "/home/creditapp/.local/lib/python3.13/site-packages/flask/app.py", line 1825, in full_dispatch_request
    rv = self.handle_user_exception(e)
  File "/home/creditapp/.local/lib/python3.13/site-packages/flask/app.py", line 1823, in full_dispatch_request
    rv = self.dispatch_request()
  File "/home/creditapp/.local/lib/python3.13/site-packages/flask/app.py", line 1799, in dispatch_request
    return self.ensure_sync(self.view_functions[rule.endpoint])(**view_args)
    return render_template('login.html')
  File "/home/creditapp/.local/lib/python3.13/site-packages/flask/templating.py", line 146, in render_template
    template = app.jinja_env.get_or_select_template(template_name_or_list)
  File "/usr/local/lib/python3.13/site-packages/jinja2/environment.py", line 1084, in get_or_select_template
    return self.get_template(template_name_or_list, parent, globals)
           ~~~~~~~~~~~~~~~~~^^^^^^^^^^^^^^^^^^^^^^^^^^^^^^^^^^^^^^^^
  File "/usr/local/lib/python3.13/site-packages/jinja2/environment.py", line 1013, in get_template
    return self._load_template(name, globals)
           ~~~~~~~~~~~~~~~~~~~^^^^^^^^^^^^^^^
  File "/usr/local/lib/python3.13/site-packages/jinja2/environment.py", line 972, in _load_template
    template = self.loader.load(self, name, self.make_globals(globals))
  File "/usr/local/lib/python3.13/site-packages/jinja2/loaders.py", line 126, in load
    source, filename, uptodate = self.get_source(environment, name)
                                 ~~~~~~~~~~~~~~~^^^^^^^^^^^^^^^^^^^
  File "/home/creditapp/.local/lib/python3.13/site-packages/flask/templating.py", line 62, in get_source
    return self._get_source_fast(environment, template)
           ~~~~~~~~~~~~~~~~~~~~~^^^^^^^^^^^^^^^^^^^^^^^
  File "/home/creditapp/.local/lib/python3.13/site-packages/flask/templating.py", line 98, in _get_source_fast
    raise TemplateNotFound(template)
jinja2.exceptions.TemplateNotFound: login.html
2025-04-28 19:52:41,839: ImportError: cannot import name 'desformatear_numero' from 'formatters' (/home/creditapp/app/formatters.py). Did you mean: 'desformatear_numero_python'?
2025-04-28 19:52:41,839:   File "/var/www/creditapp_pythonanywhere_com_wsgi.py", line 12, in <module>
2025-04-28 19:52:41,839:     from app_simple import app as application
2025-04-28 19:52:41,839: 
2025-04-28 19:52:41,839:   File "/home/creditapp/app/app_simple.py", line 18, in <module>
2025-04-28 19:52:41,839:     from formatters import formatear_numero_python, desformatear_numero
2025-04-28 19:52:41,839: ***************************************************
2025-04-28 19:52:41,839: If you're seeing an import error and don't know why,
2025-04-28 19:52:41,839: we have a dedicated help page to help you debug: 
2025-04-28 19:52:41,840: https://help.pythonanywhere.com/pages/DebuggingImportError/
2025-04-28 19:52:41,840: ***************************************************
2025-04-28 21:10:02,795: Error running WSGI application
2025-04-28 21:10:02,804: https://help.pythonanywhere.com/pages/DebuggingImportError/
2025-04-28 21:10:02,804: ***************************************************
2025-04-28 21:10:51,285: Error running WSGI application
2025-04-28 21:10:51,291: ImportError: cannot import name 'desformatear_numero' from 'formatters' (/home/creditapp/app/formatters.py). Did you mean: 'desformatear_numero_python'?
2025-04-28 21:10:51,291:   File "/var/www/creditapp_pythonanywhere_com_wsgi.py", line 20, in <module>
2025-04-28 21:10:51,291:     from app_simple import app as application
2025-04-28 21:10:51,291: 
2025-04-28 21:10:51,292:   File "/home/creditapp/app/app_simple.py", line 18, in <module>
2025-04-28 21:10:51,292: ***************************************************
2025-04-28 21:10:51,292: If you're seeing an import error and don't know why,
2025-04-28 21:10:51,292: we have a dedicated help page to help you debug: 
2025-04-28 21:10:51,293: https://help.pythonanywhere.com/pages/DebuggingImportError/
2025-04-28 21:10:51,293: ***************************************************
2025-04-28 23:56:59,037: Error running WSGI application
2025-04-28 23:56:59,044: ImportError: cannot import name 'desformatear_numero' from 'formatters' (/home/creditapp/app/formatters.py)
2025-04-28 23:56:59,044:   File "/var/www/creditapp_pythonanywhere_com_wsgi.py", line 20, in <module>
2025-04-28 23:56:59,044:     from app_simple import app as application
2025-04-28 23:56:59,044: 
2025-04-28 23:56:59,045:   File "/home/creditapp/app/app_simple.py", line 18, in <module>
2025-04-28 23:56:59,045:     from formatters import formatear_numero_python, desformatear_numero
2025-04-28 23:56:59,045: ***************************************************
2025-04-28 23:56:59,045: If you're seeing an import error and don't know why,
2025-04-28 23:56:59,045: we have a dedicated help page to help you debug: 
2025-04-28 23:56:59,045: https://help.pythonanywhere.com/pages/DebuggingImportError/
2025-04-28 23:56:59,046: ***************************************************
2025-04-29 00:06:18,628: Error running WSGI application
2025-04-29 00:06:18,642: AttributeError: module 'sqlalchemy' has no attribute '__all__'
2025-04-29 00:06:18,642:   File "/var/www/creditapp_pythonanywhere_com_wsgi.py", line 20, in <module>
2025-04-29 00:06:18,642:     from app_simple import app as application
2025-04-29 00:06:18,642: 
2025-04-29 00:06:18,642:   File "/home/creditapp/app/app_simple.py", line 29, in <module>
2025-04-29 00:06:18,643:     db = SQLAlchemy(app)
2025-04-29 00:06:18,643: 
2025-04-29 00:06:18,643:   File "/home/creditapp/.virtualenvs/creditapp-venv/lib/python3.9/site-packages/flask_sqlalchemy/__init__.py", line 758, in __init__
2025-04-29 00:06:18,643:     _include_sqlalchemy(self, query_class)
2025-04-29 00:06:18,643: 
2025-04-29 00:06:18,644:   File "/home/creditapp/.virtualenvs/creditapp-venv/lib/python3.9/site-packages/flask_sqlalchemy/__init__.py", line 112, in _include_sqlalchemy
2025-04-29 00:06:18,644:     for key in module.__all__:
2025-04-29 00:06:18,645: 
2025-04-29 00:06:18,645:   File "/home/creditapp/.virtualenvs/creditapp-venv/lib/python3.9/site-packages/sqlalchemy/__init__.py", line 294, in __getattr__
2025-04-29 00:06:18,645:     raise AttributeError(f"module {__name__!r} has no attribute {name!r}")
2025-04-29 00:06:18,645: ***************************************************
2025-04-29 00:06:18,645: If you're seeing an import error and don't know why,
2025-04-29 00:06:18,646: we have a dedicated help page to help you debug: 
2025-04-29 00:06:18,646: https://help.pythonanywhere.com/pages/DebuggingImportError/
2025-04-29 00:06:18,646: ***************************************************
Traceback (most recent call last):
  File "/home/creditapp/.virtualenvs/creditapp-venv/lib/python3.9/site-packages/flask/app.py", line 2070, in wsgi_app
    rv = self.dispatch_request()
  File "/home/creditapp/.virtualenvs/creditapp-venv/lib/python3.9/site-packages/flask/app.py", line 1499, in dispatch_request
    return self.ensure_sync(self.view_functions[rule.endpoint])(**req.view_args)
  File "/home/creditapp/app/app_simple.py", line 421, in login
    if form.validate_on_submit():
  File "/home/creditapp/.virtualenvs/creditapp-venv/lib/python3.9/site-packages/flask_wtf/form.py", line 86, in validate_on_submit
    return self.is_submitted() and self.validate()
  File "/home/creditapp/.virtualenvs/creditapp-venv/lib/python3.9/site-packages/wtforms/form.py", line 330, in validate
    return super().validate(extra)
    if not field.validate(self, extra):
  File "/home/creditapp/.virtualenvs/creditapp-venv/lib/python3.9/site-packages/wtforms/fields/core.py", line 234, in validate
    stop_validation = self._run_validation_chain(form, chain)
    raise Exception(
Exception: Install 'email_validator' for email validation support.
2025-04-29 00:30:44,093: /home/creditapp/app/app_simple.py:450: SAWarning: Dialect sqlite+pysqlite does *not* support Decimal objects natively, and SQLAlchemy must convert from floating point - rounding errors and other issues may occur. Please consider storing Decimal numbers as strings or integers on this platform for lossless storage.
2025-04-29 00:30:44,094:   total_pendiente = db.session.query(func.sum(Credito.saldo_pendiente)).filter(Credito.estado != 'Pagado').scalar() or 0
2025-04-29 00:30:44,098: /home/creditapp/app/app_simple.py:453: SAWarning: Dialect sqlite+pysqlite does *not* support Decimal objects natively, and SQLAlchemy must convert from floating point - rounding errors and other issues may occur. Please consider storing Decimal numbers as strings or integers on this platform for lossless storage.
2025-04-29 00:30:44,098:   creditos_recientes = Credito.query.order_by(Credito.fecha_creacion.desc()).limit(5).all()
2025-04-29 00:30:44,104: /home/creditapp/app/app_simple.py:456: SAWarning: Dialect sqlite+pysqlite does *not* support Decimal objects natively, and SQLAlchemy must convert from floating point - rounding errors and other issues may occur. Please consider storing Decimal numbers as strings or integers on this platform for lossless storage.
2025-04-29 00:30:44,104:   pagos_recientes = Pago.query.order_by(Pago.fecha.desc()).limit(5).all()
  File "/home/creditapp/.virtualenvs/creditapp-venv/lib/python3.9/site-packages/flask/app.py", line 1499, in dispatch_request
    return self.ensure_sync(self.view_functions[rule.endpoint])(**req.view_args)
  File "/home/creditapp/.virtualenvs/creditapp-venv/lib/python3.9/site-packages/flask_login/utils.py", line 272, in decorated_view
    return func(*args, **kwargs)
  File "/home/creditapp/app/app_simple.py", line 458, in dashboard
    return render_template('admin/dashboard.html',
  File "/home/creditapp/.virtualenvs/creditapp-venv/lib/python3.9/site-packages/flask/templating.py", line 147, in render_template
    return _render(
  File "/home/creditapp/.virtualenvs/creditapp-venv/lib/python3.9/site-packages/flask/templating.py", line 128, in _render
    rv = template.render(context)
  File "/home/creditapp/.virtualenvs/creditapp-venv/lib/python3.9/site-packages/jinja2/environment.py", line 1295, in render
    self.environment.handle_exception()
  File "/home/creditapp/.virtualenvs/creditapp-venv/lib/python3.9/site-packages/jinja2/environment.py", line 942, in handle_exception
    raise rewrite_traceback_stack(source=source)
  File "/home/creditapp/app/templates/admin/dashboard.html", line 1, in top-level template code
    {% extends "layouts/base.html" %}
  File "/home/creditapp/app/templates/layouts/base.html", line 134, in top-level template code
    {% block content %}{% endblock %}
  File "/home/creditapp/app/templates/admin/dashboard.html", line 19, in block 'content'
    <div class="text-dark fw-bold h5 mb-0 card-value"><span>{{ resumen.creditos_activos | default(0) }}</span></div>
  File "/home/creditapp/.virtualenvs/creditapp-venv/lib/python3.9/site-packages/jinja2/environment.py", line 490, in getattr
    return getattr(obj, attribute)
jinja2.exceptions.UndefinedError: 'resumen' is undefined
2025-04-29 00:41:55,840: /home/creditapp/app/app_simple.py:450: SAWarning: Dialect sqlite+pysqlite does *not* support Decimal objects natively, and SQLAlchemy must convert from floating point - rounding errors and other issues may occur. Please consider storing Decimal numbers as strings or integers on this platform for lossless storage.
2025-04-29 00:41:55,840:   total_pendiente = db.session.query(func.sum(Credito.saldo_pendiente)).filter(Credito.estado != 'Pagado').scalar() or 0
2025-04-29 00:41:55,844:   creditos_recientes = Credito.query.order_by(Credito.fecha_creacion.desc()).limit(5).all()
2025-04-29 00:41:55,848: /home/creditapp/app/app_simple.py:456: SAWarning: Dialect sqlite+pysqlite does *not* support Decimal objects natively, and SQLAlchemy must convert from floating point - rounding errors and other issues may occur. Please consider storing Decimal numbers as strings or integers on this platform for lossless storage.
2025-04-29 00:41:55,849:   pagos_recientes = Pago.query.order_by(Pago.fecha.desc()).limit(5).all()
2025-04-29 00:41:55,911: Exception on / [GET]
Traceback (most recent call last):
  File "/home/creditapp/.virtualenvs/creditapp-venv/lib/python3.9/site-packages/flask/app.py", line 2070, in wsgi_app
    response = self.full_dispatch_request()
  File "/home/creditapp/.virtualenvs/creditapp-venv/lib/python3.9/site-packages/flask/app.py", line 1515, in full_dispatch_request
    rv = self.handle_user_exception(e)
  File "/home/creditapp/.virtualenvs/creditapp-venv/lib/python3.9/site-packages/flask/app.py", line 1513, in full_dispatch_request
    rv = self.dispatch_request()
  File "/home/creditapp/.virtualenvs/creditapp-venv/lib/python3.9/site-packages/flask/app.py", line 1499, in dispatch_request
    return self.ensure_sync(self.view_functions[rule.endpoint])(**req.view_args)
  File "/home/creditapp/.virtualenvs/creditapp-venv/lib/python3.9/site-packages/flask_login/utils.py", line 272, in decorated_view
    return func(*args, **kwargs)
  File "/home/creditapp/app/app_simple.py", line 458, in dashboard
    return render_template('admin/dashboard.html',
  File "/home/creditapp/.virtualenvs/creditapp-venv/lib/python3.9/site-packages/flask/templating.py", line 147, in render_template
    return _render(
  File "/home/creditapp/.virtualenvs/creditapp-venv/lib/python3.9/site-packages/flask/templating.py", line 128, in _render
    rv = template.render(context)
  File "/home/creditapp/.virtualenvs/creditapp-venv/lib/python3.9/site-packages/jinja2/environment.py", line 1304, in render
    self.environment.handle_exception()
  File "/home/creditapp/.virtualenvs/creditapp-venv/lib/python3.9/site-packages/jinja2/environment.py", line 925, in handle_exception
    raise rewrite_traceback_stack(source=source)
  File "/home/creditapp/app/templates/admin/dashboard.html", line 1, in top-level template code
    {% extends "layouts/base.html" %}
  File "/home/creditapp/app/templates/layouts/base.html", line 134, in top-level template code
    {% block content %}{% endblock %}
  File "/home/creditapp/app/templates/admin/dashboard.html", line 19, in block 'content'
    <div class="text-dark fw-bold h5 mb-0 card-value"><span>{{ resumen.creditos_activos | default(0) }}</span></div>
  File "/home/creditapp/.virtualenvs/creditapp-venv/lib/python3.9/site-packages/jinja2/environment.py", line 474, in getattr
    return getattr(obj, attribute)
jinja2.exceptions.UndefinedError: 'resumen' is undefined
2025-04-29 00:46:31,062: /home/creditapp/app/app_simple.py:453: SAWarning: Dialect sqlite+pysqlite does *not* support Decimal objects natively, and SQLAlchemy must convert from floating point - rounding errors and other issues may occur. Please consider storing Decimal numbers as strings or integers on this platform for lossless storage.
2025-04-29 00:46:31,062:   creditos_recientes = Credito.query.order_by(Credito.fecha_creacion.desc()).limit(5).all()
2025-04-29 00:46:31,068: /home/creditapp/app/app_simple.py:456: SAWarning: Dialect sqlite+pysqlite does *not* support Decimal objects natively, and SQLAlchemy must convert from floating point - rounding errors and other issues may occur. Please consider storing Decimal numbers as strings or integers on this platform for lossless storage.
2025-04-29 00:46:31,068:   pagos_recientes = Pago.query.order_by(Pago.fecha.desc()).limit(5).all()
2025-04-29 00:46:31,117: Exception on / [GET]
2025-04-29 00:54:24,610: /home/creditapp/app/app_simple.py:453: SAWarning: Dialect sqlite+pysqlite does *not* support Decimal objects natively, and SQLAlchemy must convert from floating point - rounding errors and other issues may occur. Please consider storing Decimal numbers as strings or integers on this platform for lossless storage.
2025-04-29 00:54:24,611:   total_pendiente = db.session.query(func.sum(Credito.saldo_pendiente)).filter(Credito.estado != 'Pagado').scalar() or 0
2025-04-29 00:54:24,615: /home/creditapp/app/app_simple.py:456: SAWarning: Dialect sqlite+pysqlite does *not* support Decimal objects natively, and SQLAlchemy must convert from floating point - rounding errors and other issues may occur. Please consider storing Decimal numbers as strings or integers on this platform for lossless storage.
2025-04-29 00:54:24,615:   creditos_recientes = Credito.query.order_by(Credito.fecha_creacion.desc()).limit(5).all()
2025-04-29 00:54:24,620: /home/creditapp/app/app_simple.py:459: SAWarning: Dialect sqlite+pysqlite does *not* support Decimal objects natively, and SQLAlchemy must convert from floating point - rounding errors and other issues may occur. Please consider storing Decimal numbers as strings or integers on this platform for lossless storage.
2025-04-29 00:54:24,620:   pagos_recientes = Pago.query.order_by(Pago.fecha.desc()).limit(5).all()
    response = self.full_dispatch_request()
  File "/home/creditapp/.virtualenvs/creditapp-venv/lib/python3.9/site-packages/flask/app.py", line 1515, in full_dispatch_request
    rv = self.dispatch_request()
  File "/home/creditapp/.virtualenvs/creditapp-venv/lib/python3.9/site-packages/flask/app.py", line 1499, in dispatch_request
    return func(*args, **kwargs)
  File "/home/creditapp/.virtualenvs/creditapp-venv/lib/python3.9/site-packages/flask/templating.py", line 147, in render_template
    return _render(
    rv = template.render(context)
  File "/home/creditapp/.virtualenvs/creditapp-venv/lib/python3.9/site-packages/jinja2/environment.py", line 1304, in render
  File "/home/creditapp/app/templates/admin/dashboard.html", line 1, in top-level template code
    {% extends "layouts/base.html" %}
  File "/home/creditapp/.virtualenvs/creditapp-venv/lib/python3.9/site-packages/jinja2/environment.py", line 474, in getattr
    return getattr(obj, attribute)
2025-04-29 02:37:59,197: Exception on /dashboard [GET]
Traceback (most recent call last):
  File "/home/creditapp/.virtualenvs/creditapp-venv/lib/python3.9/site-packages/flask/app.py", line 2070, in wsgi_app
    response = self.full_dispatch_request()
  File "/home/creditapp/.virtualenvs/creditapp-venv/lib/python3.9/site-packages/flask/app.py", line 1515, in full_dispatch_request
    rv = self.handle_user_exception(e)
  File "/home/creditapp/.virtualenvs/creditapp-venv/lib/python3.9/site-packages/flask/app.py", line 1513, in full_dispatch_request
    rv = self.dispatch_request()
  File "/home/creditapp/.virtualenvs/creditapp-venv/lib/python3.9/site-packages/flask/app.py", line 1499, in dispatch_request
    return self.ensure_sync(self.view_functions[rule.endpoint])(**req.view_args)
  File "/home/creditapp/.virtualenvs/creditapp-venv/lib/python3.9/site-packages/flask_login/utils.py", line 272, in decorated_view
    return func(*args, **kwargs)
  File "/home/creditapp/app/app_simple.py", line 461, in dashboard
    return render_template('admin/dashboard.html',
  File "/home/creditapp/.virtualenvs/creditapp-venv/lib/python3.9/site-packages/flask/templating.py", line 147, in render_template
    return _render(
  File "/home/creditapp/.virtualenvs/creditapp-venv/lib/python3.9/site-packages/flask/templating.py", line 128, in _render
    rv = template.render(context)
  File "/home/creditapp/.virtualenvs/creditapp-venv/lib/python3.9/site-packages/jinja2/environment.py", line 1304, in render
    self.environment.handle_exception()
  File "/home/creditapp/.virtualenvs/creditapp-venv/lib/python3.9/site-packages/jinja2/environment.py", line 925, in handle_exception
    raise rewrite_traceback_stack(source=source)
  File "/home/creditapp/app/templates/admin/dashboard.html", line 1, in top-level template code
    {% extends "layouts/base.html" %}
  File "/home/creditapp/app/templates/layouts/base.html", line 134, in top-level template code
    {% block content %}{% endblock %}
  File "/home/creditapp/app/templates/admin/dashboard.html", line 19, in block 'content'
    <div class="text-dark fw-bold h5 mb-0 card-value"><span>{{ resumen.creditos_activos | default(0) }}</span></div>
  File "/home/creditapp/.virtualenvs/creditapp-venv/lib/python3.9/site-packages/jinja2/environment.py", line 474, in getattr
    return getattr(obj, attribute)
jinja2.exceptions.UndefinedError: 'resumen' is undefined
2025-04-29 02:38:16,227: Exception on /dashboard [GET]
Traceback (most recent call last):
  File "/home/creditapp/.virtualenvs/creditapp-venv/lib/python3.9/site-packages/flask/app.py", line 2070, in wsgi_app
    response = self.full_dispatch_request()
  File "/home/creditapp/.virtualenvs/creditapp-venv/lib/python3.9/site-packages/flask/app.py", line 1515, in full_dispatch_request
    rv = self.handle_user_exception(e)
  File "/home/creditapp/.virtualenvs/creditapp-venv/lib/python3.9/site-packages/flask/app.py", line 1513, in full_dispatch_request
    rv = self.dispatch_request()
  File "/home/creditapp/.virtualenvs/creditapp-venv/lib/python3.9/site-packages/flask/app.py", line 1499, in dispatch_request
    return self.ensure_sync(self.view_functions[rule.endpoint])(**req.view_args)
  File "/home/creditapp/.virtualenvs/creditapp-venv/lib/python3.9/site-packages/flask_login/utils.py", line 272, in decorated_view
    return func(*args, **kwargs)
  File "/home/creditapp/app/app_simple.py", line 461, in dashboard
    return render_template('admin/dashboard.html',
  File "/home/creditapp/.virtualenvs/creditapp-venv/lib/python3.9/site-packages/flask/templating.py", line 147, in render_template
    return _render(
  File "/home/creditapp/.virtualenvs/creditapp-venv/lib/python3.9/site-packages/flask/templating.py", line 128, in _render
    rv = template.render(context)
  File "/home/creditapp/.virtualenvs/creditapp-venv/lib/python3.9/site-packages/jinja2/environment.py", line 1304, in render
    self.environment.handle_exception()
  File "/home/creditapp/.virtualenvs/creditapp-venv/lib/python3.9/site-packages/jinja2/environment.py", line 925, in handle_exception
    raise rewrite_traceback_stack(source=source)
  File "/home/creditapp/app/templates/admin/dashboard.html", line 1, in top-level template code
    {% extends "layouts/base.html" %}
  File "/home/creditapp/app/templates/layouts/base.html", line 134, in top-level template code
    {% block content %}{% endblock %}
  File "/home/creditapp/app/templates/admin/dashboard.html", line 19, in block 'content'
    <div class="text-dark fw-bold h5 mb-0 card-value"><span>{{ resumen.creditos_activos | default(0) }}</span></div>
  File "/home/creditapp/.virtualenvs/creditapp-venv/lib/python3.9/site-packages/jinja2/environment.py", line 474, in getattr
    return getattr(obj, attribute)
jinja2.exceptions.UndefinedError: 'resumen' is undefined
2025-04-29 02:38:21,602: Exception on /dashboard [GET]
Traceback (most recent call last):
  File "/home/creditapp/.virtualenvs/creditapp-venv/lib/python3.9/site-packages/flask/app.py", line 2070, in wsgi_app
    response = self.full_dispatch_request()
  File "/home/creditapp/.virtualenvs/creditapp-venv/lib/python3.9/site-packages/flask/app.py", line 1515, in full_dispatch_request
    rv = self.handle_user_exception(e)
  File "/home/creditapp/.virtualenvs/creditapp-venv/lib/python3.9/site-packages/flask/app.py", line 1513, in full_dispatch_request
    rv = self.dispatch_request()
  File "/home/creditapp/.virtualenvs/creditapp-venv/lib/python3.9/site-packages/flask/app.py", line 1499, in dispatch_request
    return self.ensure_sync(self.view_functions[rule.endpoint])(**req.view_args)
  File "/home/creditapp/.virtualenvs/creditapp-venv/lib/python3.9/site-packages/flask_login/utils.py", line 272, in decorated_view
    return func(*args, **kwargs)
  File "/home/creditapp/app/app_simple.py", line 461, in dashboard
    return render_template('admin/dashboard.html',
  File "/home/creditapp/.virtualenvs/creditapp-venv/lib/python3.9/site-packages/flask/templating.py", line 147, in render_template
    return _render(
  File "/home/creditapp/.virtualenvs/creditapp-venv/lib/python3.9/site-packages/flask/templating.py", line 128, in _render
    rv = template.render(context)
  File "/home/creditapp/.virtualenvs/creditapp-venv/lib/python3.9/site-packages/jinja2/environment.py", line 1304, in render
    self.environment.handle_exception()
  File "/home/creditapp/.virtualenvs/creditapp-venv/lib/python3.9/site-packages/jinja2/environment.py", line 925, in handle_exception
    raise rewrite_traceback_stack(source=source)
  File "/home/creditapp/app/templates/admin/dashboard.html", line 1, in top-level template code
    {% extends "layouts/base.html" %}
  File "/home/creditapp/app/templates/layouts/base.html", line 134, in top-level template code
  File "/home/creditapp/app/templates/admin/dashboard.html", line 19, in block 'content'
    <div class="text-dark fw-bold h5 mb-0 card-value"><span>{{ resumen.creditos_activos | default(0) }}</span></div>
  File "/home/creditapp/.virtualenvs/creditapp-venv/lib/python3.9/site-packages/jinja2/environment.py", line 474, in getattr
    return getattr(obj, attribute)
jinja2.exceptions.UndefinedError: 'resumen' is undefined
2025-04-29 02:45:09,222: /home/creditapp/app/app_simple.py:454: SAWarning: Dialect sqlite+pysqlite does *not* support Decimal objects natively, and SQLAlchemy must convert from floating point - rounding errors and other issues may occur. Please consider storing Decimal numbers as strings or integers on this platform for lossless storage.
2025-04-29 02:45:09,222:   saldo_total_pendiente = db.session.query(func.coalesce(func.sum(Credito.saldo_pendiente), Decimal(0)))\
2025-04-29 02:45:09,234: /home/creditapp/app/app_simple.py:470: SAWarning: Dialect sqlite+pysqlite does *not* support Decimal objects natively, and SQLAlchemy must convert from floating point - rounding errors and other issues may occur. Please consider storing Decimal numbers as strings or integers on this platform for lossless storage.
2025-04-29 02:45:09,235:   creditos_recientes = Credito.query.order_by(Credito.fecha_creacion.desc()).limit(5).all()
2025-04-29 02:45:09,245: /home/creditapp/app/app_simple.py:472: SAWarning: Dialect sqlite+pysqlite does *not* support Decimal objects natively, and SQLAlchemy must convert from floating point - rounding errors and other issues may occur. Please consider storing Decimal numbers as strings or integers on this platform for lossless storage.
2025-04-29 02:45:09,246:   pagos_recientes = Pago.query.order_by(Pago.fecha.desc()).limit(5).all()
2025-04-29 02:46:47,570: Exception on /crear_usuario [GET]
Traceback (most recent call last):
  File "/home/creditapp/.virtualenvs/creditapp-venv/lib/python3.9/site-packages/flask/app.py", line 2070, in wsgi_app
    response = self.full_dispatch_request()
  File "/home/creditapp/.virtualenvs/creditapp-venv/lib/python3.9/site-packages/flask/app.py", line 1515, in full_dispatch_request
    rv = self.handle_user_exception(e)
  File "/home/creditapp/.virtualenvs/creditapp-venv/lib/python3.9/site-packages/flask/app.py", line 1513, in full_dispatch_request
    rv = self.dispatch_request()
  File "/home/creditapp/.virtualenvs/creditapp-venv/lib/python3.9/site-packages/flask/app.py", line 1499, in dispatch_request
    return self.ensure_sync(self.view_functions[rule.endpoint])(**req.view_args)
  File "/home/creditapp/.virtualenvs/creditapp-venv/lib/python3.9/site-packages/flask_login/utils.py", line 272, in decorated_view
    return func(*args, **kwargs)
  File "/home/creditapp/app/app_simple.py", line 524, in crear_usuario
    return render_template('admin/form_usuario.html', form=form)
  File "/home/creditapp/.virtualenvs/creditapp-venv/lib/python3.9/site-packages/flask/templating.py", line 147, in render_template
    return _render(
  File "/home/creditapp/.virtualenvs/creditapp-venv/lib/python3.9/site-packages/flask/templating.py", line 128, in _render
    rv = template.render(context)
  File "/home/creditapp/.virtualenvs/creditapp-venv/lib/python3.9/site-packages/jinja2/environment.py", line 1304, in render
    self.environment.handle_exception()
  File "/home/creditapp/.virtualenvs/creditapp-venv/lib/python3.9/site-packages/jinja2/environment.py", line 925, in handle_exception
    raise rewrite_traceback_stack(source=source)
  File "/home/creditapp/app/templates/admin/form_usuario.html", line 1, in top-level template code
    {% extends "layouts/base.html" %}
  File "/home/creditapp/app/templates/layouts/base.html", line 134, in top-level template code
    {% block content %}{% endblock %}
  File "/home/creditapp/app/templates/admin/form_usuario.html", line 72, in block 'content'
    {{ form.confirm_password.label(class="form-label required") }}
  File "/home/creditapp/.virtualenvs/creditapp-venv/lib/python3.9/site-packages/jinja2/environment.py", line 474, in getattr
    return getattr(obj, attribute)
jinja2.exceptions.UndefinedError: 'app_simple.UsuarioForm object' has no attribute 'confirm_password'
2025-04-29 02:53:26,013: /home/creditapp/app/app_simple.py:709: SAWarning: Dialect sqlite+pysqlite does *not* support Decimal objects natively, and SQLAlchemy must convert from floating point - rounding errors and other issues may occur. Please consider storing Decimal numbers as strings or integers on this platform for lossless storage.
2025-04-29 02:53:26,014:   form.vendedor_id.choices = [(v.id, v.nombre) for v in Vendedor.query.filter_by(activo=True).all()]
2025-04-29 02:53:26,046: Exception on /crear_credito [GET]
Traceback (most recent call last):
  File "/home/creditapp/.virtualenvs/creditapp-venv/lib/python3.9/site-packages/flask/app.py", line 2070, in wsgi_app
    response = self.full_dispatch_request()
  File "/home/creditapp/.virtualenvs/creditapp-venv/lib/python3.9/site-packages/flask/app.py", line 1515, in full_dispatch_request
    rv = self.handle_user_exception(e)
  File "/home/creditapp/.virtualenvs/creditapp-venv/lib/python3.9/site-packages/flask/app.py", line 1513, in full_dispatch_request
    rv = self.dispatch_request()
  File "/home/creditapp/.virtualenvs/creditapp-venv/lib/python3.9/site-packages/flask/app.py", line 1499, in dispatch_request
    return self.ensure_sync(self.view_functions[rule.endpoint])(**req.view_args)
  File "/home/creditapp/.virtualenvs/creditapp-venv/lib/python3.9/site-packages/flask_login/utils.py", line 272, in decorated_view
    return func(*args, **kwargs)
  File "/home/creditapp/app/app_simple.py", line 776, in crear_credito
    return render_template('creditos/crear_credito.html', form=form)
  File "/home/creditapp/.virtualenvs/creditapp-venv/lib/python3.9/site-packages/flask/templating.py", line 147, in render_template
    return _render(
  File "/home/creditapp/.virtualenvs/creditapp-venv/lib/python3.9/site-packages/flask/templating.py", line 128, in _render
    rv = template.render(context)
  File "/home/creditapp/.virtualenvs/creditapp-venv/lib/python3.9/site-packages/jinja2/environment.py", line 1304, in render
    self.environment.handle_exception()
  File "/home/creditapp/.virtualenvs/creditapp-venv/lib/python3.9/site-packages/jinja2/environment.py", line 925, in handle_exception
    raise rewrite_traceback_stack(source=source)
  File "/home/creditapp/app/templates/creditos/crear_credito.html", line 1, in top-level template code
    {% extends "layouts/base.html" %}
  File "/home/creditapp/app/templates/layouts/base.html", line 134, in top-level template code
    {% block content %}{% endblock %}
  File "/home/creditapp/app/templates/creditos/crear_credito.html", line 17, in block 'content'
    {{ form.items_json(id="items_json") }} {# Campo oculto para enviar el carrito #}
    if hasattr(obj, "jinja_pass_arg"):
jinja2.exceptions.UndefinedError: 'app_simple.CreditoForm object' has no attribute 'items_json'
2025-04-29 02:54:16,004: Exception on /crear_credito [GET]
Traceback (most recent call last):
  File "/home/creditapp/.virtualenvs/creditapp-venv/lib/python3.9/site-packages/flask/app.py", line 2070, in wsgi_app
    response = self.full_dispatch_request()
  File "/home/creditapp/.virtualenvs/creditapp-venv/lib/python3.9/site-packages/flask/app.py", line 1515, in full_dispatch_request
    rv = self.handle_user_exception(e)
  File "/home/creditapp/.virtualenvs/creditapp-venv/lib/python3.9/site-packages/flask/app.py", line 1513, in full_dispatch_request
    rv = self.dispatch_request()
  File "/home/creditapp/.virtualenvs/creditapp-venv/lib/python3.9/site-packages/flask/app.py", line 1499, in dispatch_request
    return self.ensure_sync(self.view_functions[rule.endpoint])(**req.view_args)
  File "/home/creditapp/.virtualenvs/creditapp-venv/lib/python3.9/site-packages/flask_login/utils.py", line 272, in decorated_view
    return func(*args, **kwargs)
  File "/home/creditapp/app/app_simple.py", line 776, in crear_credito
    return render_template('creditos/crear_credito.html', form=form)
  File "/home/creditapp/.virtualenvs/creditapp-venv/lib/python3.9/site-packages/flask/templating.py", line 147, in render_template
    return _render(
  File "/home/creditapp/.virtualenvs/creditapp-venv/lib/python3.9/site-packages/flask/templating.py", line 128, in _render
    rv = template.render(context)
  File "/home/creditapp/.virtualenvs/creditapp-venv/lib/python3.9/site-packages/jinja2/environment.py", line 1304, in render
    self.environment.handle_exception()
  File "/home/creditapp/.virtualenvs/creditapp-venv/lib/python3.9/site-packages/jinja2/environment.py", line 925, in handle_exception
    raise rewrite_traceback_stack(source=source)
  File "/home/creditapp/app/templates/creditos/crear_credito.html", line 1, in top-level template code
    {% extends "layouts/base.html" %}
  File "/home/creditapp/app/templates/layouts/base.html", line 134, in top-level template code
    {% block content %}{% endblock %}
  File "/home/creditapp/app/templates/creditos/crear_credito.html", line 17, in block 'content'
    {{ form.items_json(id="items_json") }} {# Campo oculto para enviar el carrito #}
  File "/home/creditapp/.virtualenvs/creditapp-venv/lib/python3.9/site-packages/jinja2/utils.py", line 84, in from_obj
    if hasattr(obj, "jinja_pass_arg"):
jinja2.exceptions.UndefinedError: 'app_simple.CreditoForm object' has no attribute 'items_json'
2025-04-29 02:54:19,783: Exception on /crear_credito [GET]
Traceback (most recent call last):
  File "/home/creditapp/.virtualenvs/creditapp-venv/lib/python3.9/site-packages/flask/app.py", line 2070, in wsgi_app
    response = self.full_dispatch_request()
  File "/home/creditapp/.virtualenvs/creditapp-venv/lib/python3.9/site-packages/flask/app.py", line 1515, in full_dispatch_request
    rv = self.handle_user_exception(e)
  File "/home/creditapp/.virtualenvs/creditapp-venv/lib/python3.9/site-packages/flask/app.py", line 1513, in full_dispatch_request
    rv = self.dispatch_request()
  File "/home/creditapp/.virtualenvs/creditapp-venv/lib/python3.9/site-packages/flask/app.py", line 1499, in dispatch_request
    return self.ensure_sync(self.view_functions[rule.endpoint])(**req.view_args)
  File "/home/creditapp/.virtualenvs/creditapp-venv/lib/python3.9/site-packages/flask_login/utils.py", line 272, in decorated_view
    return func(*args, **kwargs)
  File "/home/creditapp/app/app_simple.py", line 776, in crear_credito
    return render_template('creditos/crear_credito.html', form=form)
    return _render(
  File "/home/creditapp/.virtualenvs/creditapp-venv/lib/python3.9/site-packages/flask/templating.py", line 128, in _render
    rv = template.render(context)
  File "/home/creditapp/.virtualenvs/creditapp-venv/lib/python3.9/site-packages/jinja2/environment.py", line 1304, in render
    self.environment.handle_exception()
  File "/home/creditapp/.virtualenvs/creditapp-venv/lib/python3.9/site-packages/jinja2/environment.py", line 925, in handle_exception
    raise rewrite_traceback_stack(source=source)
  File "/home/creditapp/app/templates/creditos/crear_credito.html", line 1, in top-level template code
    {% extends "layouts/base.html" %}
  File "/home/creditapp/app/templates/layouts/base.html", line 134, in top-level template code
    {% block content %}{% endblock %}
  File "/home/creditapp/app/templates/creditos/crear_credito.html", line 17, in block 'content'
    {{ form.items_json(id="items_json") }} {# Campo oculto para enviar el carrito #}
  File "/home/creditapp/.virtualenvs/creditapp-venv/lib/python3.9/site-packages/jinja2/utils.py", line 84, in from_obj
    if hasattr(obj, "jinja_pass_arg"):
jinja2.exceptions.UndefinedError: 'app_simple.CreditoForm object' has no attribute 'items_json'
2025-04-29 02:54:21,904: /home/creditapp/.virtualenvs/creditapp-venv/lib/python3.9/site-packages/flask_sqlalchemy/__init__.py:534: SAWarning: Dialect sqlite+pysqlite does *not* support Decimal objects natively, and SQLAlchemy must convert from floating point - rounding errors and other issues may occur. Please consider storing Decimal numbers as strings or integers on this platform for lossless storage.
2025-04-29 02:54:21,904:   items = self.limit(per_page).offset((page - 1) * per_page).all()
2025-04-29 02:54:25,105: Exception on /crear_producto [GET]
Traceback (most recent call last):
  File "/home/creditapp/.virtualenvs/creditapp-venv/lib/python3.9/site-packages/flask/app.py", line 2070, in wsgi_app
    response = self.full_dispatch_request()
  File "/home/creditapp/.virtualenvs/creditapp-venv/lib/python3.9/site-packages/flask/app.py", line 1515, in full_dispatch_request
    rv = self.handle_user_exception(e)
  File "/home/creditapp/.virtualenvs/creditapp-venv/lib/python3.9/site-packages/flask/app.py", line 1513, in full_dispatch_request
    rv = self.dispatch_request()
  File "/home/creditapp/.virtualenvs/creditapp-venv/lib/python3.9/site-packages/flask/app.py", line 1499, in dispatch_request
    return self.ensure_sync(self.view_functions[rule.endpoint])(**req.view_args)
  File "/home/creditapp/.virtualenvs/creditapp-venv/lib/python3.9/site-packages/flask_login/utils.py", line 272, in decorated_view
    return func(*args, **kwargs)
  File "/home/creditapp/app/app_simple.py", line 961, in crear_producto
    return render_template('inventario/form_producto.html', form=form)
  File "/home/creditapp/.virtualenvs/creditapp-venv/lib/python3.9/site-packages/flask/templating.py", line 148, in render_template
    ctx.app.jinja_env.get_or_select_template(template_name_or_list),
  File "/home/creditapp/.virtualenvs/creditapp-venv/lib/python3.9/site-packages/jinja2/environment.py", line 1068, in get_or_select_template
    return self.get_template(template_name_or_list, parent, globals)
  File "/home/creditapp/.virtualenvs/creditapp-venv/lib/python3.9/site-packages/jinja2/environment.py", line 997, in get_template
    return self._load_template(name, globals)
  File "/home/creditapp/.virtualenvs/creditapp-venv/lib/python3.9/site-packages/jinja2/environment.py", line 958, in _load_template
    template = self.loader.load(self, name, self.make_globals(globals))
  File "/home/creditapp/.virtualenvs/creditapp-venv/lib/python3.9/site-packages/jinja2/loaders.py", line 125, in load
    source, filename, uptodate = self.get_source(environment, name)
  File "/home/creditapp/.virtualenvs/creditapp-venv/lib/python3.9/site-packages/flask/templating.py", line 59, in get_source
    return self._get_source_fast(environment, template)
  File "/home/creditapp/.virtualenvs/creditapp-venv/lib/python3.9/site-packages/flask/templating.py", line 95, in _get_source_fast
    raise TemplateNotFound(template)
jinja2.exceptions.TemplateNotFound: inventario/form_producto.html
2025-04-29 02:57:27,675: /home/creditapp/app/app_simple.py:1191: SAWarning: Dialect sqlite+pysqlite does *not* support Decimal objects natively, and SQLAlchemy must convert from floating point - rounding errors and other issues may occur. Please consider storing Decimal numbers as strings or integers on this platform for lossless storage.
2025-04-29 02:57:27,675:   total_ingresos = db.session.query(func.sum(MovimientoCaja.monto)).filter(
2025-04-29 02:57:27,694: /home/creditapp/app/app_simple.py:1202: SAWarning: Dialect sqlite+pysqlite does *not* support Decimal objects natively, and SQLAlchemy must convert from floating point - rounding errors and other issues may occur. Please consider storing Decimal numbers as strings or integers on this platform for lossless storage.
2025-04-29 03:14:38,080: Exception on /calcular_comisiones [GET]
Traceback (most recent call last):
  File "/home/creditapp/.virtualenvs/creditapp-venv/lib/python3.9/site-packages/flask/app.py", line 2070, in wsgi_app
    response = self.full_dispatch_request()
  File "/home/creditapp/.virtualenvs/creditapp-venv/lib/python3.9/site-packages/flask/app.py", line 1515, in full_dispatch_request
    rv = self.handle_user_exception(e)
  File "/home/creditapp/.virtualenvs/creditapp-venv/lib/python3.9/site-packages/flask/app.py", line 1513, in full_dispatch_request
    rv = self.dispatch_request()
  File "/home/creditapp/.virtualenvs/creditapp-venv/lib/python3.9/site-packages/flask/app.py", line 1499, in dispatch_request
    return self.ensure_sync(self.view_functions[rule.endpoint])(**req.view_args)
  File "/home/creditapp/.virtualenvs/creditapp-venv/lib/python3.9/site-packages/flask_login/utils.py", line 272, in decorated_view
    return func(*args, **kwargs)
  File "/home/creditapp/app/app_simple.py", line 1520, in calcular_comisiones
    return render_template('finanzas/calcular_comisiones.html',
  File "/home/creditapp/.virtualenvs/creditapp-venv/lib/python3.9/site-packages/flask/templating.py", line 148, in render_template
    ctx.app.jinja_env.get_or_select_template(template_name_or_list),
  File "/home/creditapp/.virtualenvs/creditapp-venv/lib/python3.9/site-packages/jinja2/environment.py", line 1068, in get_or_select_template
    return self.get_template(template_name_or_list, parent, globals)
  File "/home/creditapp/.virtualenvs/creditapp-venv/lib/python3.9/site-packages/jinja2/environment.py", line 997, in get_template
    return self._load_template(name, globals)
  File "/home/creditapp/.virtualenvs/creditapp-venv/lib/python3.9/site-packages/jinja2/environment.py", line 958, in _load_template
    template = self.loader.load(self, name, self.make_globals(globals))
  File "/home/creditapp/.virtualenvs/creditapp-venv/lib/python3.9/site-packages/jinja2/loaders.py", line 125, in load
    source, filename, uptodate = self.get_source(environment, name)
  File "/home/creditapp/.virtualenvs/creditapp-venv/lib/python3.9/site-packages/flask/templating.py", line 59, in get_source
    return self._get_source_fast(environment, template)
  File "/home/creditapp/.virtualenvs/creditapp-venv/lib/python3.9/site-packages/flask/templating.py", line 95, in _get_source_fast
    raise TemplateNotFound(template)
jinja2.exceptions.TemplateNotFound: finanzas/calcular_comisiones.html
2025-04-29 03:15:45,162: Exception on /calcular_comisiones [GET]
Traceback (most recent call last):
  File "/home/creditapp/.virtualenvs/creditapp-venv/lib/python3.9/site-packages/flask/app.py", line 2070, in wsgi_app
    response = self.full_dispatch_request()
  File "/home/creditapp/.virtualenvs/creditapp-venv/lib/python3.9/site-packages/flask/app.py", line 1515, in full_dispatch_request
    rv = self.handle_user_exception(e)
  File "/home/creditapp/.virtualenvs/creditapp-venv/lib/python3.9/site-packages/flask/app.py", line 1513, in full_dispatch_request
    rv = self.dispatch_request()
  File "/home/creditapp/.virtualenvs/creditapp-venv/lib/python3.9/site-packages/flask/app.py", line 1499, in dispatch_request
    return self.ensure_sync(self.view_functions[rule.endpoint])(**req.view_args)
  File "/home/creditapp/.virtualenvs/creditapp-venv/lib/python3.9/site-packages/flask_login/utils.py", line 272, in decorated_view
    return func(*args, **kwargs)
  File "/home/creditapp/app/app_simple.py", line 1520, in calcular_comisiones
    return render_template('finanzas/calcular_comisiones.html',
  File "/home/creditapp/.virtualenvs/creditapp-venv/lib/python3.9/site-packages/flask/templating.py", line 148, in render_template
    ctx.app.jinja_env.get_or_select_template(template_name_or_list),
  File "/home/creditapp/.virtualenvs/creditapp-venv/lib/python3.9/site-packages/jinja2/environment.py", line 1068, in get_or_select_template
    return self.get_template(template_name_or_list, parent, globals)
  File "/home/creditapp/.virtualenvs/creditapp-venv/lib/python3.9/site-packages/jinja2/environment.py", line 997, in get_template
    return self._load_template(name, globals)
  File "/home/creditapp/.virtualenvs/creditapp-venv/lib/python3.9/site-packages/jinja2/environment.py", line 958, in _load_template
    template = self.loader.load(self, name, self.make_globals(globals))
  File "/home/creditapp/.virtualenvs/creditapp-venv/lib/python3.9/site-packages/jinja2/loaders.py", line 125, in load
    source, filename, uptodate = self.get_source(environment, name)
  File "/home/creditapp/.virtualenvs/creditapp-venv/lib/python3.9/site-packages/flask/templating.py", line 59, in get_source
    return self._get_source_fast(environment, template)
  File "/home/creditapp/.virtualenvs/creditapp-venv/lib/python3.9/site-packages/flask/templating.py", line 95, in _get_source_fast
    raise TemplateNotFound(template)
jinja2.exceptions.TemplateNotFound: finanzas/calcular_comisiones.html
2025-04-29 03:15:47,555: Exception on /calcular_comisiones [GET]
Traceback (most recent call last):
  File "/home/creditapp/.virtualenvs/creditapp-venv/lib/python3.9/site-packages/flask/app.py", line 2070, in wsgi_app
    response = self.full_dispatch_request()
  File "/home/creditapp/.virtualenvs/creditapp-venv/lib/python3.9/site-packages/flask/app.py", line 1515, in full_dispatch_request
    rv = self.handle_user_exception(e)
  File "/home/creditapp/.virtualenvs/creditapp-venv/lib/python3.9/site-packages/flask/app.py", line 1513, in full_dispatch_request
    rv = self.dispatch_request()
  File "/home/creditapp/.virtualenvs/creditapp-venv/lib/python3.9/site-packages/flask/app.py", line 1499, in dispatch_request
    return self.ensure_sync(self.view_functions[rule.endpoint])(**req.view_args)
  File "/home/creditapp/.virtualenvs/creditapp-venv/lib/python3.9/site-packages/flask_login/utils.py", line 272, in decorated_view
    return func(*args, **kwargs)
  File "/home/creditapp/app/app_simple.py", line 1520, in calcular_comisiones
    return render_template('finanzas/calcular_comisiones.html',
  File "/home/creditapp/.virtualenvs/creditapp-venv/lib/python3.9/site-packages/flask/templating.py", line 148, in render_template
    ctx.app.jinja_env.get_or_select_template(template_name_or_list),
  File "/home/creditapp/.virtualenvs/creditapp-venv/lib/python3.9/site-packages/jinja2/environment.py", line 1068, in get_or_select_template
    return self.get_template(template_name_or_list, parent, globals)
  File "/home/creditapp/.virtualenvs/creditapp-venv/lib/python3.9/site-packages/jinja2/environment.py", line 997, in get_template
    return self._load_template(name, globals)
  File "/home/creditapp/.virtualenvs/creditapp-venv/lib/python3.9/site-packages/jinja2/environment.py", line 958, in _load_template
    template = self.loader.load(self, name, self.make_globals(globals))
  File "/home/creditapp/.virtualenvs/creditapp-venv/lib/python3.9/site-packages/jinja2/loaders.py", line 125, in load
    source, filename, uptodate = self.get_source(environment, name)
  File "/home/creditapp/.virtualenvs/creditapp-venv/lib/python3.9/site-packages/flask/templating.py", line 59, in get_source
    return self._get_source_fast(environment, template)
  File "/home/creditapp/.virtualenvs/creditapp-venv/lib/python3.9/site-packages/flask/templating.py", line 95, in _get_source_fast
    raise TemplateNotFound(template)
jinja2.exceptions.TemplateNotFound: finanzas/calcular_comisiones.html
2025-04-29 03:17:58,148: Exception on /crear_usuario [GET]
Traceback (most recent call last):
  File "/home/creditapp/.virtualenvs/creditapp-venv/lib/python3.9/site-packages/flask/app.py", line 2070, in wsgi_app
    response = self.full_dispatch_request()
  File "/home/creditapp/.virtualenvs/creditapp-venv/lib/python3.9/site-packages/flask/app.py", line 1515, in full_dispatch_request
    rv = self.handle_user_exception(e)
  File "/home/creditapp/.virtualenvs/creditapp-venv/lib/python3.9/site-packages/flask/app.py", line 1513, in full_dispatch_request
    rv = self.dispatch_request()
  File "/home/creditapp/.virtualenvs/creditapp-venv/lib/python3.9/site-packages/flask/app.py", line 1499, in dispatch_request
    return self.ensure_sync(self.view_functions[rule.endpoint])(**req.view_args)
  File "/home/creditapp/.virtualenvs/creditapp-venv/lib/python3.9/site-packages/flask_login/utils.py", line 272, in decorated_view
    return func(*args, **kwargs)
  File "/home/creditapp/app/app_simple.py", line 524, in crear_usuario
    return render_template('admin/form_usuario.html', form=form)
  File "/home/creditapp/.virtualenvs/creditapp-venv/lib/python3.9/site-packages/flask/templating.py", line 147, in render_template
    return _render(
  File "/home/creditapp/.virtualenvs/creditapp-venv/lib/python3.9/site-packages/flask/templating.py", line 128, in _render
    rv = template.render(context)
  File "/home/creditapp/.virtualenvs/creditapp-venv/lib/python3.9/site-packages/jinja2/environment.py", line 1304, in render
    self.environment.handle_exception()
  File "/home/creditapp/.virtualenvs/creditapp-venv/lib/python3.9/site-packages/jinja2/environment.py", line 925, in handle_exception
    raise rewrite_traceback_stack(source=source)
  File "/home/creditapp/app/templates/admin/form_usuario.html", line 1, in top-level template code
    {% extends "layouts/base.html" %}
  File "/home/creditapp/app/templates/layouts/base.html", line 134, in top-level template code
    {% block content %}{% endblock %}
  File "/home/creditapp/app/templates/admin/form_usuario.html", line 72, in block 'content'
    {{ form.confirm_password.label(class="form-label required") }}
  File "/home/creditapp/.virtualenvs/creditapp-venv/lib/python3.9/site-packages/jinja2/environment.py", line 474, in getattr
    return getattr(obj, attribute)
jinja2.exceptions.UndefinedError: 'app_simple.UsuarioForm object' has no attribute 'confirm_password'
2025-04-29 03:18:13,691: Exception on /crear_usuario [GET]
Traceback (most recent call last):
  File "/home/creditapp/.virtualenvs/creditapp-venv/lib/python3.9/site-packages/flask/app.py", line 2070, in wsgi_app
    response = self.full_dispatch_request()
  File "/home/creditapp/.virtualenvs/creditapp-venv/lib/python3.9/site-packages/flask/app.py", line 1515, in full_dispatch_request
    rv = self.handle_user_exception(e)
  File "/home/creditapp/.virtualenvs/creditapp-venv/lib/python3.9/site-packages/flask/app.py", line 1513, in full_dispatch_request
    rv = self.dispatch_request()
  File "/home/creditapp/.virtualenvs/creditapp-venv/lib/python3.9/site-packages/flask/app.py", line 1499, in dispatch_request
    return self.ensure_sync(self.view_functions[rule.endpoint])(**req.view_args)
  File "/home/creditapp/.virtualenvs/creditapp-venv/lib/python3.9/site-packages/flask_login/utils.py", line 272, in decorated_view
    return func(*args, **kwargs)
  File "/home/creditapp/app/app_simple.py", line 524, in crear_usuario
    return render_template('admin/form_usuario.html', form=form)
  File "/home/creditapp/.virtualenvs/creditapp-venv/lib/python3.9/site-packages/flask/templating.py", line 147, in render_template
    return _render(
  File "/home/creditapp/.virtualenvs/creditapp-venv/lib/python3.9/site-packages/flask/templating.py", line 128, in _render
    rv = template.render(context)
  File "/home/creditapp/.virtualenvs/creditapp-venv/lib/python3.9/site-packages/jinja2/environment.py", line 1304, in render
    self.environment.handle_exception()
  File "/home/creditapp/.virtualenvs/creditapp-venv/lib/python3.9/site-packages/jinja2/environment.py", line 925, in handle_exception
    raise rewrite_traceback_stack(source=source)
  File "/home/creditapp/app/templates/admin/form_usuario.html", line 1, in top-level template code
    {% extends "layouts/base.html" %}
  File "/home/creditapp/app/templates/layouts/base.html", line 134, in top-level template code
    {% block content %}{% endblock %}
  File "/home/creditapp/app/templates/admin/form_usuario.html", line 72, in block 'content'
    {{ form.confirm_password.label(class="form-label required") }}
  File "/home/creditapp/.virtualenvs/creditapp-venv/lib/python3.9/site-packages/jinja2/environment.py", line 474, in getattr
    return getattr(obj, attribute)
jinja2.exceptions.UndefinedError: 'app_simple.UsuarioForm object' has no attribute 'confirm_password'
2025-04-29 13:16:48,324: Exception on /crear_usuario [GET]
Traceback (most recent call last):
  File "/home/creditapp/.virtualenvs/creditapp-venv/lib/python3.9/site-packages/flask/app.py", line 2070, in wsgi_app
    response = self.full_dispatch_request()
  File "/home/creditapp/.virtualenvs/creditapp-venv/lib/python3.9/site-packages/flask/app.py", line 1515, in full_dispatch_request
    rv = self.handle_user_exception(e)
  File "/home/creditapp/.virtualenvs/creditapp-venv/lib/python3.9/site-packages/flask/app.py", line 1513, in full_dispatch_request
    rv = self.dispatch_request()
  File "/home/creditapp/.virtualenvs/creditapp-venv/lib/python3.9/site-packages/flask/app.py", line 1499, in dispatch_request
    return self.ensure_sync(self.view_functions[rule.endpoint])(**req.view_args)
  File "/home/creditapp/.virtualenvs/creditapp-venv/lib/python3.9/site-packages/flask_login/utils.py", line 272, in decorated_view
    return func(*args, **kwargs)
  File "/home/creditapp/app/app_simple.py", line 524, in crear_usuario
    return render_template('admin/form_usuario.html', form=form)
  File "/home/creditapp/.virtualenvs/creditapp-venv/lib/python3.9/site-packages/flask/templating.py", line 147, in render_template
    return _render(
  File "/home/creditapp/.virtualenvs/creditapp-venv/lib/python3.9/site-packages/flask/templating.py", line 128, in _render
    rv = template.render(context)
  File "/home/creditapp/.virtualenvs/creditapp-venv/lib/python3.9/site-packages/jinja2/environment.py", line 1304, in render
    self.environment.handle_exception()
  File "/home/creditapp/.virtualenvs/creditapp-venv/lib/python3.9/site-packages/jinja2/environment.py", line 925, in handle_exception
    raise rewrite_traceback_stack(source=source)
  File "/home/creditapp/app/templates/admin/form_usuario.html", line 1, in top-level template code
    {% extends "layouts/base.html" %}
  File "/home/creditapp/app/templates/layouts/base.html", line 134, in top-level template code
    {% block content %}{% endblock %}
  File "/home/creditapp/app/templates/admin/form_usuario.html", line 72, in block 'content'
    {{ form.confirm_password.label(class="form-label required") }}
  File "/home/creditapp/.virtualenvs/creditapp-venv/lib/python3.9/site-packages/jinja2/environment.py", line 474, in getattr
    return getattr(obj, attribute)
jinja2.exceptions.UndefinedError: 'app_simple.UsuarioForm object' has no attribute 'confirm_password'
2025-04-29 13:17:00,711: Exception on /crear_cliente [POST]
Traceback (most recent call last):
  File "/home/creditapp/.virtualenvs/creditapp-venv/lib/python3.9/site-packages/sqlalchemy/engine/base.py", line 1910, in _execute_context
    self.dialect.do_execute(
  File "/home/creditapp/.virtualenvs/creditapp-venv/lib/python3.9/site-packages/sqlalchemy/engine/default.py", line 736, in do_execute
    cursor.execute(statement, parameters)
sqlite3.IntegrityError: UNIQUE constraint failed: cliente.documento
**NO MATCH**
The above exception was the direct cause of the following exception:
**NO MATCH**
Traceback (most recent call last):
  File "/home/creditapp/.virtualenvs/creditapp-venv/lib/python3.9/site-packages/flask/app.py", line 2070, in wsgi_app
    response = self.full_dispatch_request()
  File "/home/creditapp/.virtualenvs/creditapp-venv/lib/python3.9/site-packages/flask/app.py", line 1515, in full_dispatch_request
    rv = self.handle_user_exception(e)
  File "/home/creditapp/.virtualenvs/creditapp-venv/lib/python3.9/site-packages/flask/app.py", line 1513, in full_dispatch_request
    rv = self.dispatch_request()
  File "/home/creditapp/.virtualenvs/creditapp-venv/lib/python3.9/site-packages/flask/app.py", line 1499, in dispatch_request
    return self.ensure_sync(self.view_functions[rule.endpoint])(**req.view_args)
  File "/home/creditapp/.virtualenvs/creditapp-venv/lib/python3.9/site-packages/flask_login/utils.py", line 272, in decorated_view
    return func(*args, **kwargs)
  File "/home/creditapp/app/app_simple.py", line 616, in crear_cliente
    db.session.commit()
  File "<string>", line 2, in commit
  File "/home/creditapp/.virtualenvs/creditapp-venv/lib/python3.9/site-packages/sqlalchemy/orm/session.py", line 1454, in commit
    self._transaction.commit(_to_root=self.future)
  File "/home/creditapp/.virtualenvs/creditapp-venv/lib/python3.9/site-packages/sqlalchemy/orm/session.py", line 832, in commit
    self._prepare_impl()
  File "/home/creditapp/.virtualenvs/creditapp-venv/lib/python3.9/site-packages/sqlalchemy/orm/session.py", line 811, in _prepare_impl
    self.session.flush()
  File "/home/creditapp/.virtualenvs/creditapp-venv/lib/python3.9/site-packages/sqlalchemy/orm/session.py", line 3449, in flush
    self._flush(objects)
  File "/home/creditapp/.virtualenvs/creditapp-venv/lib/python3.9/site-packages/sqlalchemy/orm/session.py", line 3589, in _flush
    transaction.rollback(_capture_exception=True)
  File "/home/creditapp/.virtualenvs/creditapp-venv/lib/python3.9/site-packages/sqlalchemy/util/langhelpers.py", line 70, in __exit__
    compat.raise_(
  File "/home/creditapp/.virtualenvs/creditapp-venv/lib/python3.9/site-packages/sqlalchemy/util/compat.py", line 211, in raise_
    raise exception
  File "/home/creditapp/.virtualenvs/creditapp-venv/lib/python3.9/site-packages/sqlalchemy/orm/session.py", line 3549, in _flush
    flush_context.execute()
  File "/home/creditapp/.virtualenvs/creditapp-venv/lib/python3.9/site-packages/sqlalchemy/orm/unitofwork.py", line 456, in execute
    rec.execute(self)
  File "/home/creditapp/.virtualenvs/creditapp-venv/lib/python3.9/site-packages/sqlalchemy/orm/unitofwork.py", line 630, in execute
    util.preloaded.orm_persistence.save_obj(
  File "/home/creditapp/.virtualenvs/creditapp-venv/lib/python3.9/site-packages/sqlalchemy/orm/persistence.py", line 245, in save_obj
    _emit_insert_statements(
  File "/home/creditapp/.virtualenvs/creditapp-venv/lib/python3.9/site-packages/sqlalchemy/orm/persistence.py", line 1238, in _emit_insert_statements
    raise exception
  File "/home/creditapp/.virtualenvs/creditapp-venv/lib/python3.9/site-packages/sqlalchemy/engine/base.py", line 1910, in _execute_context
    self.dialect.do_execute(
  File "/home/creditapp/.virtualenvs/creditapp-venv/lib/python3.9/site-packages/sqlalchemy/engine/default.py", line 736, in do_execute
    cursor.execute(statement, parameters)
sqlalchemy.exc.IntegrityError: (sqlite3.IntegrityError) UNIQUE constraint failed: cliente.documento
[SQL: INSERT INTO cliente (nombre, documento, telefono, email, direccion, notas, activo, fecha_creacion) VALUES (?, ?, ?, ?, ?, ?, ?, ?)]
[parameters: ('teresa', '854121', '', 'mortertdsdsdsa@gmail.com', 'obando', '', 0, '2025-04-29 13:17:00.702613')]
(Background on this error at: https://sqlalche.me/e/14/gkpj)
2025-04-29 13:17:06,294: Exception on /crear_credito [GET]
Traceback (most recent call last):
  File "/home/creditapp/.virtualenvs/creditapp-venv/lib/python3.9/site-packages/flask/app.py", line 2070, in wsgi_app
    response = self.full_dispatch_request()
  File "/home/creditapp/.virtualenvs/creditapp-venv/lib/python3.9/site-packages/flask/app.py", line 1515, in full_dispatch_request
    rv = self.handle_user_exception(e)
  File "/home/creditapp/.virtualenvs/creditapp-venv/lib/python3.9/site-packages/flask/app.py", line 1513, in full_dispatch_request
    rv = self.dispatch_request()
  File "/home/creditapp/.virtualenvs/creditapp-venv/lib/python3.9/site-packages/flask/app.py", line 1499, in dispatch_request
    return self.ensure_sync(self.view_functions[rule.endpoint])(**req.view_args)
  File "/home/creditapp/.virtualenvs/creditapp-venv/lib/python3.9/site-packages/flask_login/utils.py", line 272, in decorated_view
    return func(*args, **kwargs)
  File "/home/creditapp/app/app_simple.py", line 776, in crear_credito
    return render_template('creditos/crear_credito.html', form=form)
  File "/home/creditapp/.virtualenvs/creditapp-venv/lib/python3.9/site-packages/flask/templating.py", line 147, in render_template
    return _render(
  File "/home/creditapp/.virtualenvs/creditapp-venv/lib/python3.9/site-packages/flask/templating.py", line 128, in _render
    rv = template.render(context)
  File "/home/creditapp/.virtualenvs/creditapp-venv/lib/python3.9/site-packages/jinja2/environment.py", line 1304, in render
    self.environment.handle_exception()
  File "/home/creditapp/.virtualenvs/creditapp-venv/lib/python3.9/site-packages/jinja2/environment.py", line 925, in handle_exception
    raise rewrite_traceback_stack(source=source)
  File "/home/creditapp/app/templates/creditos/crear_credito.html", line 1, in top-level template code
    {% extends "layouts/base.html" %}
  File "/home/creditapp/app/templates/layouts/base.html", line 134, in top-level template code
    {% block content %}{% endblock %}
  File "/home/creditapp/app/templates/creditos/crear_credito.html", line 17, in block 'content'
    {{ form.items_json(id="items_json") }} {# Campo oculto para enviar el carrito #}
  File "/home/creditapp/.virtualenvs/creditapp-venv/lib/python3.9/site-packages/jinja2/utils.py", line 84, in from_obj
    if hasattr(obj, "jinja_pass_arg"):
jinja2.exceptions.UndefinedError: 'app_simple.CreditoForm object' has no attribute 'items_json'
2025-04-29 13:17:11,573: Exception on /crear_producto [GET]
Traceback (most recent call last):
  File "/home/creditapp/.virtualenvs/creditapp-venv/lib/python3.9/site-packages/flask/app.py", line 2070, in wsgi_app
    response = self.full_dispatch_request()
  File "/home/creditapp/.virtualenvs/creditapp-venv/lib/python3.9/site-packages/flask/app.py", line 1515, in full_dispatch_request
    rv = self.handle_user_exception(e)
  File "/home/creditapp/.virtualenvs/creditapp-venv/lib/python3.9/site-packages/flask/app.py", line 1513, in full_dispatch_request
    rv = self.dispatch_request()
  File "/home/creditapp/.virtualenvs/creditapp-venv/lib/python3.9/site-packages/flask/app.py", line 1499, in dispatch_request
    return self.ensure_sync(self.view_functions[rule.endpoint])(**req.view_args)
  File "/home/creditapp/.virtualenvs/creditapp-venv/lib/python3.9/site-packages/flask_login/utils.py", line 272, in decorated_view
    return func(*args, **kwargs)
  File "/home/creditapp/app/app_simple.py", line 961, in crear_producto
    return render_template('inventario/form_producto.html', form=form)
  File "/home/creditapp/.virtualenvs/creditapp-venv/lib/python3.9/site-packages/flask/templating.py", line 148, in render_template
    ctx.app.jinja_env.get_or_select_template(template_name_or_list),
  File "/home/creditapp/.virtualenvs/creditapp-venv/lib/python3.9/site-packages/jinja2/environment.py", line 1068, in get_or_select_template
    return self.get_template(template_name_or_list, parent, globals)
  File "/home/creditapp/.virtualenvs/creditapp-venv/lib/python3.9/site-packages/jinja2/environment.py", line 997, in get_template
    return self._load_template(name, globals)
  File "/home/creditapp/.virtualenvs/creditapp-venv/lib/python3.9/site-packages/jinja2/environment.py", line 958, in _load_template
    template = self.loader.load(self, name, self.make_globals(globals))
  File "/home/creditapp/.virtualenvs/creditapp-venv/lib/python3.9/site-packages/jinja2/loaders.py", line 125, in load
    source, filename, uptodate = self.get_source(environment, name)
  File "/home/creditapp/.virtualenvs/creditapp-venv/lib/python3.9/site-packages/flask/templating.py", line 59, in get_source
    return self._get_source_fast(environment, template)
  File "/home/creditapp/.virtualenvs/creditapp-venv/lib/python3.9/site-packages/flask/templating.py", line 95, in _get_source_fast
    raise TemplateNotFound(template)
jinja2.exceptions.TemplateNotFound: inventario/form_producto.html
2025-04-29 13:19:26,594: Exception on /calcular_comisiones [GET]
Traceback (most recent call last):
  File "/home/creditapp/.virtualenvs/creditapp-venv/lib/python3.9/site-packages/flask/app.py", line 2070, in wsgi_app
    response = self.full_dispatch_request()
  File "/home/creditapp/.virtualenvs/creditapp-venv/lib/python3.9/site-packages/flask/app.py", line 1515, in full_dispatch_request
    rv = self.handle_user_exception(e)
  File "/home/creditapp/.virtualenvs/creditapp-venv/lib/python3.9/site-packages/flask/app.py", line 1513, in full_dispatch_request
    rv = self.dispatch_request()
  File "/home/creditapp/.virtualenvs/creditapp-venv/lib/python3.9/site-packages/flask/app.py", line 1499, in dispatch_request
    return self.ensure_sync(self.view_functions[rule.endpoint])(**req.view_args)
  File "/home/creditapp/.virtualenvs/creditapp-venv/lib/python3.9/site-packages/flask_login/utils.py", line 272, in decorated_view
    return func(*args, **kwargs)
  File "/home/creditapp/app/app_simple.py", line 1520, in calcular_comisiones
    return render_template('finanzas/calcular_comisiones.html',
  File "/home/creditapp/.virtualenvs/creditapp-venv/lib/python3.9/site-packages/flask/templating.py", line 148, in render_template
    ctx.app.jinja_env.get_or_select_template(template_name_or_list),
  File "/home/creditapp/.virtualenvs/creditapp-venv/lib/python3.9/site-packages/jinja2/environment.py", line 1068, in get_or_select_template
    return self.get_template(template_name_or_list, parent, globals)
  File "/home/creditapp/.virtualenvs/creditapp-venv/lib/python3.9/site-packages/jinja2/environment.py", line 997, in get_template
    return self._load_template(name, globals)
  File "/home/creditapp/.virtualenvs/creditapp-venv/lib/python3.9/site-packages/jinja2/environment.py", line 958, in _load_template
    template = self.loader.load(self, name, self.make_globals(globals))
  File "/home/creditapp/.virtualenvs/creditapp-venv/lib/python3.9/site-packages/jinja2/loaders.py", line 125, in load
    source, filename, uptodate = self.get_source(environment, name)
  File "/home/creditapp/.virtualenvs/creditapp-venv/lib/python3.9/site-packages/flask/templating.py", line 59, in get_source
    return self._get_source_fast(environment, template)
  File "/home/creditapp/.virtualenvs/creditapp-venv/lib/python3.9/site-packages/flask/templating.py", line 95, in _get_source_fast
    raise TemplateNotFound(template)
jinja2.exceptions.TemplateNotFound: finanzas/calcular_comisiones.html
2025-04-29 13:19:34,486: Exception on /calcular_comisiones [GET]
Traceback (most recent call last):
  File "/home/creditapp/.virtualenvs/creditapp-venv/lib/python3.9/site-packages/flask/app.py", line 2070, in wsgi_app
    response = self.full_dispatch_request()
  File "/home/creditapp/.virtualenvs/creditapp-venv/lib/python3.9/site-packages/flask/app.py", line 1515, in full_dispatch_request
    rv = self.handle_user_exception(e)
  File "/home/creditapp/.virtualenvs/creditapp-venv/lib/python3.9/site-packages/flask/app.py", line 1513, in full_dispatch_request
    rv = self.dispatch_request()
  File "/home/creditapp/.virtualenvs/creditapp-venv/lib/python3.9/site-packages/flask/app.py", line 1499, in dispatch_request
    return self.ensure_sync(self.view_functions[rule.endpoint])(**req.view_args)
  File "/home/creditapp/.virtualenvs/creditapp-venv/lib/python3.9/site-packages/jinja2/environment.py", line 997, in get_template
    return self._load_template(name, globals)
  File "/home/creditapp/.virtualenvs/creditapp-venv/lib/python3.9/site-packages/jinja2/environment.py", line 958, in _load_template
    template = self.loader.load(self, name, self.make_globals(globals))
  File "/home/creditapp/.virtualenvs/creditapp-venv/lib/python3.9/site-packages/jinja2/loaders.py", line 125, in load
    source, filename, uptodate = self.get_source(environment, name)
  File "/home/creditapp/.virtualenvs/creditapp-venv/lib/python3.9/site-packages/flask/templating.py", line 59, in get_source
    return self._get_source_fast(environment, template)
  File "/home/creditapp/.virtualenvs/creditapp-venv/lib/python3.9/site-packages/flask/templating.py", line 95, in _get_source_fast
    raise TemplateNotFound(template)
jinja2.exceptions.TemplateNotFound: finanzas/calcular_comisiones.html
